Workbook

Sheet 巡视
A1: 2025-2026学年高二第一学期期中考
A2: 一、组织管理
A3: 主考： | B3: 杨兵
A4: 副主考： | B4: 李宗蔚
A5: 巡视： | B5: 黄华
A6: 考务 | B6: 收发卷 | C6: 李丹凝、蓝昊荣、黄丹娴、肖洋
B7: 铃声 | C7: 陈映儿
A8: 考务室：三楼报告厅1 考务培训时间：11月4日（周二）下午15：45 地点：三楼报告厅1
A9: 二、监考要求
A10: 1、考务室地点：三楼报告厅1 2、签到领试卷时间：提前30分钟签到。 3、收、发试卷要求：按指令要求收发卷、答题卡、草稿纸。考试结束，按高考要求收齐答题卡、在答题卡袋面写实考人数，缺考的不用收。 4、监考员要求：规范、严格，如需离开考场超过15分钟必须向主考报备。 5、学生要求：1、中途不能上洗手间。（确实身体不舒服的，报巡考员，由巡考带去） 2、不能提前交卷。
A11: 三、考场板书
A12: 考试科目：** 考试时间：**到** 试卷页数：** 答题卡页数：**

Sheet 铃声安排
A1: =巡视!A1&"铃声安排" -> 2025-2026学年高二第一学期期中考铃声安排
A2: 11月5日（周三） | D2: 11月6日（周四）
A3: 7:20分响铃（上自习铃声。跟平时一致，有预备铃跟正铃）
A4: 7:30分响铃（下自习铃声）
A5: 时间 | B5: 指令 | D5: 时间 | E5: 指令
A6: 语文考试 | D6: 4选2考试
A7: 0.33333333 | B7: 0.4375 | D7: 0.33333333 | E7: 0.44791667
A8: =A7-"0:20" -> 0.31944444 | B8: 响铃（学生要到座位就坐完毕） | D8: =D7-"0:20" -> 0.31944444 | E8: 响铃（学生要到座位就坐完毕）
A9: =A8+"0:05" -> 0.32291667 | B9: 响铃（发答题卡草稿纸） | D9: =D8+"0:05" -> 0.32291667 | E9: 响铃（发答题卡草稿纸）
A10: =A9+"0:05" -> 0.32638889 | B10: 响铃（启封试卷袋，整理试卷） | D10: =D9+"0:05" -> 0.32638889 | E10: 响铃（启封试卷袋，整理试卷）
A11: =A10+"0:05" -> 0.32986111 | B11: 响铃（发试卷） | D11: =D10+"0:05" -> 0.32986111 | E11: 响铃（发试卷）
A12: =A11+"0:05" -> 0.33333333 | B12: 响铃（考试开始，开始作答） | D12: =D11+"0:05" -> 0.33333333 | E12: 响铃（考试开始，开始作答）
A13: =A14-"0:15" -> 0.42708333 | B13: 响铃（离考试结束还有15分钟） | D13: =D14-"0:15" -> 0.375 | E13: 响铃（离考试结束还有15分钟）
A14: =B7 -> 0.4375 | B14: 响铃（考试结束） | D14: 0.38541667 | E14: 响铃（考试结束）
D15: =D14+"0:05" -> 0.38888889 | E15: 响铃（发答题卡草稿纸）
D16: 0.39236111 | E16: 响铃（发试卷）
D17: =D16+"0:05" -> 0.39583333 | E17: 响铃（考试开始，开始作答）
D18: =D19-"0:15" -> 0.4375 | E18: 响铃（离考试结束还有15分钟）
D19: 0.44791667 | E19: 响铃（考试结束）
A21: 物理/历史考试 | D21: 自习
A22: 0.45833333 | B22: 0.51041667 | D22: 0.46875 | E22: 0.51041667
A23: =A22-"0:20" -> 0.44444444 | B23: 响铃（学生要到座位就坐完毕） | D23: =D22 -> 0.46875 | E23: 上课铃
A24: =A23+"0:05" -> 0.44791667 | B24: 响铃（发答题卡草稿纸）
A25: =A24+"0:05" -> 0.45138889 | B25: 响铃（启封试卷袋，整理试卷）
A26: =A25+"0:05" -> 0.45486111 | B26: 响铃（发试卷）
A27: =A26+"0:05" -> 0.45833333 | B27: 响铃（考试开始，开始作答）
A28: =A29-"0:15" -> 0.5 | B28: 响铃（离考试结束还有15分钟）
A29: =B22 -> 0.51041667 | B29: 响铃（考试结束） | D29: =E22 -> 0.51041667 | E29: 下课铃
A31: 数学考试 | D31: 英语考试
A32: 0.60416667 | B32: 0.6875 | D32: 0.60416667 | E32: 0.6875
A33: =A32-"0:20" -> 0.59027778 | B33: 响铃（学生要到座位就坐完毕） | D33: =D32-"0:20" -> 0.59027778 | E33: 响铃（学生要到座位就坐完毕）
A34: =A33+"0:05" -> 0.59375 | B34: 响铃（发答题卡草稿纸） | D34: =D33+"0:05" -> 0.59375 | E34: 响铃（发答题卡草稿纸）
A35: =A34+"0:05" -> 0.59722222 | B35: 响铃（启封试卷袋，整理试卷） | D35: =D34+"0:05" -> 0.59722222 | E35: 响铃（启封试卷袋，整理试卷）
A36: =A35+"0:05" -> 0.60069444 | B36: 响铃（发试卷） | D36: =D35+"0:05" -> 0.60069444 | E36: 响铃（发试卷）
A37: =A36+"0:05" -> 0.60416667 | B37: 响铃（考试开始，开始作答） | D37: =D36+"0:05" -> 0.60416667 | E37: 响铃（考试开始，开始作答）
A38: =A39-"0:15" -> 0.67708333 | B38: 响铃（离考试结束还有15分钟） | D38: =D39-"0:15" -> 0.67708333 | E38: 响铃（离考试结束还有15分钟）
A39: =B32 -> 0.6875 | B39: 响铃（考试结束） | D39: =E32 -> 0.6875 | E39: 响铃（考试结束）
A41: 政治学考 | D41: 物理学考
A42: 0.70833333 | B42: 0.75 | D42: 0.70833333 | E42: 0.75
A43: =A42-"0:20" -> 0.69444444 | B43: 响铃（学生要到座位就坐完毕） | D43: =D42-"0:20" -> 0.69444444 | E43: 响铃（学生要到座位就坐完毕）
...

Sheet 监考安排
A1: =巡视!$A$1&"监考安排" -> 2025-2026学年高二第一学期期中考监考安排 | Q1: =IF(COUNTIF(T4:AA53,">1")>0,FALSE,TRUE) -> TRUE | T1: 11月5日（周三） | X1: 11月6日（周四）
A2: 试室 | B2: 人数 | C2: 11月5日（周三） | J2: 11月6日（周四） | T2: 语文 | U2: 物理/历史 | V2: 数学 | W2: 政治学考 | X2: 4选2 | Y2: 自习 | Z2: 英语 | AA2: 物理学考
C3: 8:00-10:30 语文 | E3: 11:00-12:15 物理/历史 | G3: 14:30-16:30 数学 | I3: 17:00-18:00 政治学考 | J3: 8:00-10:45 4选2 | L3: 11:15-12:15 自习 | M3: 14:30-16:30 英语 | O3: 17:00-18:00 物理学考 | Q3: 姓名 | R3: 段数 | S3: 时长 | T3: 8:00-10:30 | U3: 11:00-12:15 | V3: 14:30-16:30 | W3: 17:00-18:00 | X3: 8:00-10:45 | Y3: 11:15-12:15 | Z3: 14:30-16:30 | AA3: 17:00-18:00 | AD3: 物理 | AE3: 历史 | AF3: 化学 | AG3: 生物 | AH3: 地理 | AI3: 政治 | AK3: 语文20考场 | AL3: 20*45 | AM3: =20*45 -> 900 | AN3: 50 | AO3: =AM3+AN3 -> 950
A4: 高二1班 | B4: =COUNTIFS(学生编排结果!$H:$H,A4) -> 42 | C4: 蒋思明 | D4: 吕雪容 | E4: 杨眉 | F4: 张馨予 | G4: 郑婉慧 | H4: 黄朝阳 | I4: 陈美苑 | J4: 张莉萍 | K4: 杨眉 | L4: 杨眉 | M4: 陈晓迪 | N4: 黄朝阳 | O4: 马嘉骏 | Q4: 林蕴瑜 | R4: =COUNTIFS($C$4:$O$23,Q4) -> 5 | S4: =+T4*150+U4*75+V4*120+W4*60+X4*165+Y4*60+Z4*120+AA4*60 -> 465 | T4: =COUNTIFS($C$4:$D$23,Q4) -> 1 | U4: =COUNTIFS($E$4:$F$23,Q4) -> 1 | V4: =COUNTIFS($G$4:$H$23,Q4) -> 0 | W4: =COUNTIFS($I$4:$I$23,Q4) -> 0 | X4: =COUNTIFS($J$4:$K$23,Q4) -> 0 | Y4: =COUNTIFS($L$4:$L$23,Q4) -> 1 | Z4: =COUNTIFS($M$4:$N$23,Q4) -> 1 | AA4: =COUNTIFS($O$4:$O$23,Q4) -> 1 | AC4: 高二1班 | AD4: 42 | AE4: 0 | AF4: 42 | AG4: 42 | AH4: 0 | AI4: 0 | AK4: 数学20考场 | AL4: 20*45 | AM4: =20*45 -> 900 | AN4: 50 | AO4: =AM4+AN4 -> 950
A5: 高二2班 | B5: =COUNTIFS(学生编排结果!$H:$H,A5) -> 42 | C5: 王倩 | E5: 李昕雨 | G5: 王玉发 | I5: 王菲飞 | J5: 余晓娜 | L5: 李智芳 | M5: 王玉发 | O5: 陈映儿 | Q5: 明珊珊 | R5: =COUNTIFS($C$4:$O$23,Q5) -> 5 | S5: =+T5*150+U5*75+V5*120+W5*60+X5*165+Y5*60+Z5*120+AA5*60 -> 465 | T5: =COUNTIFS($C$4:$D$23,Q5) -> 1 | U5: =COUNTIFS($E$4:$F$23,Q5) -> 1 | V5: =COUNTIFS($G$4:$H$23,Q5) -> 0 | W5: =COUNTIFS($I$4:$I$23,Q5) -> 0 | X5: =COUNTIFS($J$4:$K$23,Q5) -> 0 | Y5: =COUNTIFS($L$4:$L$23,Q5) -> 1 | Z5: =COUNTIFS($M$4:$N$23,Q5) -> 1 | AA5: =COUNTIFS($O$4:$O$23,Q5) -> 1 | AC5: 高二2班 | AD5: 42 | AE5: 0 | AF5: 42 | AG5: 42 | AH5: 0 | AI5: 0 | AK5: 英语20考场 | AL5: 20*45 | AM5: =20*45 -> 900 | AN5: 50 | AO5: =AM5+AN5 -> 950
A6: 高二3班 | B6: =COUNTIFS(学生编排结果!$H:$H,A6) -> 42 | C6: 马嘉骏 | D6: 张光礼 | E6: 王昕 | F6: 李嘉燕 | G6: 刘小洪 | H6: 蒋红 | I6: 蒋思明 | J6: 王倩 | K6: 谢晨阳 | L6: 张莉萍 | M6: 刘小洪 | N6: 蒋红 | O6: 明珊珊 | Q6: 蒋思明 | R6: =COUNTIFS($C$4:$O$23,Q6) -> 5 | S6: =+T6*150+U6*75+V6*120+W6*60+X6*165+Y6*60+Z6*120+AA6*60 -> 465 | T6: =COUNTIFS($C$4:$D$23,Q6) -> 1 | U6: =COUNTIFS($E$4:$F$23,Q6) -> 1 | V6: =COUNTIFS($G$4:$H$23,Q6) -> 1 | W6: =COUNTIFS($I$4:$I$23,Q6) -> 1 | X6: =COUNTIFS($J$4:$K$23,Q6) -> 0 | Y6: =COUNTIFS($L$4:$L$23,Q6) -> 1 | Z6: =COUNTIFS($M$4:$N$23,Q6) -> 0 | AA6: =COUNTIFS($O$4:$O$23,Q6) -> 0 | AC6: 高二3班 | AD6: 42 | AE6: 0 | AF6: 42 | AG6: 42 | AH6: 0 | AI6: 0 | AK6: 物理15考场 | AL6: 15*45 | AM6: =15*45 -> 675 | AN6: 50 | AO6: =AM6+AN6 -> 725
A7: 高二4班 | B7: =COUNTIFS(学生编排结果!$H:$H,A7) -> 42 | C7: 余晓娜 | E7: 王海劲 | G7: 钟日明 | I7: 吕雪容 | J7: 李智芳 | L7: 张馨予 | M7: 钟日明 | O7: 梁洁楹 | Q7: 吕雪容 | R7: =COUNTIFS($C$4:$O$23,Q7) -> 5 | S7: =+T7*150+U7*75+V7*120+W7*60+X7*165+Y7*60+Z7*120+AA7*60 -> 465 | T7: =COUNTIFS($C$4:$D$23,Q7) -> 1 | U7: =COUNTIFS($E$4:$F$23,Q7) -> 1 | V7: =COUNTIFS($G$4:$H$23,Q7) -> 1 | W7: =COUNTIFS($I$4:$I$23,Q7) -> 1 | X7: =COUNTIFS($J$4:$K$23,Q7) -> 0 | Y7: =COUNTIFS($L$4:$L$23,Q7) -> 1 | Z7: =COUNTIFS($M$4:$N$23,Q7) -> 0 | AA7: =COUNTIFS($O$4:$O$23,Q7) -> 0 | AC7: 高二4班 | AD7: 42 | AE7: 0 | AF7: 42 | AG7: 42 | AH7: 0 | AI7: 0 | AK7: 历史5考场 | AL7: 5*45 | AM7: =5*45 -> 225 | AN7: 25 | AO7: =AM7+AN7 -> 250
A8: 高二5班 | B8: =COUNTIFS(学生编排结果!$H:$H,A8) -> 42 | C8: 林蕴瑜 | D8: 谢晨阳 | E8: 李镇国 | F8: 马嘉骏 | G8: 钟三明 | H8: 张玉静 | I8: 彭海影 | J8: 张馨予 | K8: 李昕雨 | L8: 李昕雨 | M8: 张玉静 | N8: 孙静 | O8: 林蕴瑜 | Q8: 彭海影 | R8: =COUNTIFS($C$4:$O$23,Q8) -> 5 | S8: =+T8*150+U8*75+V8*120+W8*60+X8*165+Y8*60+Z8*120+AA8*60 -> 450 | T8: =COUNTIFS($C$4:$D$23,Q8) -> 1 | U8: =COUNTIFS($E$4:$F$23,Q8) -> 0 | V8: =COUNTIFS($G$4:$H$23,Q8) -> 0 | W8: =COUNTIFS($I$4:$I$23,Q8) -> 1 | X8: =COUNTIFS($J$4:$K$23,Q8) -> 0 | Y8: =COUNTIFS($L$4:$L$23,Q8) -> 1 | Z8: =COUNTIFS($M$4:$N$23,Q8) -> 1 | AA8: =COUNTIFS($O$4:$O$23,Q8) -> 1 | AC8: 高二5班 | AD8: 42 | AE8: 0 | AF8: 42 | AG8: 42 | AH8: 0 | AI8: 0 | AK8: 化学16考场 | AL8: 16*45 | AM8: =16*45 -> 720 | AN8: 0 | AO8: =AM8+AN8 -> 720
A9: 高二6班 | B9: =COUNTIFS(学生编排结果!$H:$H,A9) -> 42 | C9: 范南莺 | E9: 林蕴瑜 | G9: 孙静 | I9: 李昕雨 | J9: 李嘉燕 | L9: 李嘉燕 | M9: 许业琳 | O9: 许业琳 | Q9: 张光礼 | R9: =COUNTIFS($C$4:$O$23,Q9) -> 3 | S9: =+T9*150+U9*75+V9*120+W9*60+X9*165+Y9*60+Z9*120+AA9*60 -> 345 | T9: =COUNTIFS($C$4:$D$23,Q9) -> 1 | U9: =COUNTIFS($E$4:$F$23,Q9) -> 1 | V9: =COUNTIFS($G$4:$H$23,Q9) -> 0 | W9: =COUNTIFS($I$4:$I$23,Q9) -> 0 | X9: =COUNTIFS($J$4:$K$23,Q9) -> 0 | Y9: =COUNTIFS($L$4:$L$23,Q9) -> 0 | Z9: =COUNTIFS($M$4:$N$23,Q9) -> 1 | AA9: =COUNTIFS($O$4:$O$23,Q9) -> 0 | AC9: 高二6班 | AD9: 42 | AE9: 0 | AF9: 42 | AG9: 42 | AH9: 0 | AI9: 0 | AK9: 生物12考场 | AL9: 12*45 | AM9: =12*45 -> 540 | AN9: 0 | AO9: =AM9+AN9 -> 540
A10: 高二7班 | B10: =COUNTIFS(学生编排结果!$H:$H,A10) -> 42 | C10: 周罗洁 | D10: 张莉萍 | E10: 明珊珊 | F10: 贺育林 | G10: 贺育林 | H10: 黄楚琪 | I10: 赵香甜 | J10: 陈映儿 | K10: 王菲飞 | L10: 林蕴瑜 | M10: 侯文娟 | N10: 刘艳 | O10: 余晓娜 | Q10: 赵香甜 | R10: =COUNTIFS($C$4:$O$23,Q10) -> 5 | S10: =+T10*150+U10*75+V10*120+W10*60+X10*165+Y10*60+Z10*120+AA10*60 -> 465 | T10: =COUNTIFS($C$4:$D$23,Q10) -> 1 | U10: =COUNTIFS($E$4:$F$23,Q10) -> 1 | V10: =COUNTIFS($G$4:$H$23,Q10) -> 0 | W10: =COUNTIFS($I$4:$I$23,Q10) -> 1 | X10: =COUNTIFS($J$4:$K$23,Q10) -> 0 | Y10: =COUNTIFS($L$4:$L$23,Q10) -> 1 | Z10: =COUNTIFS($M$4:$N$23,Q10) -> 1 | AA10: =COUNTIFS($O$4:$O$23,Q10) -> 0 | AC10: 高二7班 | AD10: 42 | AE10: 0 | AF10: 42 | AG10: 42 | AH10: 0 | AI10: 0 | AK10: 地理8考场 | AL10: 8*45 | AM10: =8*45 -> 360 | AN10: 0 | AO10: =AM10+AN10 -> 360
A11: 高二8班 | B11: =COUNTIFS(学生编排结果!$H:$H,A11) -> 42 | C11: 赵香甜 | E11: 黄楚琪 | G11: 许业琳 | I11: 段蕴瑶 | J11: 张妮 | L11: 明珊珊 | M11: 范南莺 | O11: 王倩 | Q11: 段蕴瑶 | R11: =COUNTIFS($C$4:$O$23,Q11) -> 5 | S11: =+T11*150+U11*75+V11*120+W11*60+X11*165+Y11*60+Z11*120+AA11*60 -> 465 | T11: =COUNTIFS($C$4:$D$23,Q11) -> 1 | U11: =COUNTIFS($E$4:$F$23,Q11) -> 1 | V11: =COUNTIFS($G$4:$H$23,Q11) -> 0 | W11: =COUNTIFS($I$4:$I$23,Q11) -> 1 | X11: =COUNTIFS($J$4:$K$23,Q11) -> 0 | Y11: =COUNTIFS($L$4:$L$23,Q11) -> 1 | Z11: =COUNTIFS($M$4:$N$23,Q11) -> 1 | AA11: =COUNTIFS($O$4:$O$23,Q11) -> 0 | AC11: 高二8班 | AD11: 42 | AE11: 0 | AF11: 42 | AG11: 42 | AH11: 0 | AI11: 0 | AK11: 政治7考场 | AL11: 7*45 | AM11: =7*45 -> 315 | AO11: =AM11+AN11 -> 315
A12: 高二9班 | B12: =COUNTIFS(学生编排结果!$H:$H,A12) -> 42 | C12: 段蕴瑶 | D12: 杨眉 | E12: 许业琳 | F12: 余晓娜 | G12: 陈坚 | H12: 刘良桂 | I12: 钟三明 | J12: 梁洁楹 | K12: 陈美苑 | L12: 蒋思明 | M12: 王菲飞 | N12: 王帅 | O12: 谢晨阳 | Q12: 钟三明 | R12: =COUNTIFS($C$4:$O$23,Q12) -> 4 | S12: =+T12*150+U12*75+V12*120+W12*60+X12*165+Y12*60+Z12*120+AA12*60 -> 465 | T12: =COUNTIFS($C$4:$D$23,Q12) -> 0 | U12: =COUNTIFS($E$4:$F$23,Q12) -> 0 | V12: =COUNTIFS($G$4:$H$23,Q12) -> 1 | W12: =COUNTIFS($I$4:$I$23,Q12) -> 1 | X12: =COUNTIFS($J$4:$K$23,Q12) -> 1 | Y12: =COUNTIFS($L$4:$L$23,Q12) -> 0 | Z12: =COUNTIFS($M$4:$N$23,Q12) -> 1 | AA12: =COUNTIFS($O$4:$O$23,Q12) -> 0 | AC12: 高二9班 | AD12: 42 | AE12: 0 | AF12: 42 | AG12: 42 | AH12: 0 | AI12: 0
A13: 高二10班 | B13: =COUNTIFS(学生编排结果!$H:$H,A13) -> 42 | C13: 曹芳 | E13: 王倩 | G13: 张妮 | I13: 曹芳 | J13: 蒋虹 | L13: 吕雪容 | M13: 明珊珊 | O13: 范南莺 | Q13: 曹芳 | R13: =COUNTIFS($C$4:$O$23,Q13) -> 5 | S13: =+T13*150+U13*75+V13*120+W13*60+X13*165+Y13*60+Z13*120+AA13*60 -> 465 | T13: =COUNTIFS($C$4:$D$23,Q13) -> 1 | U13: =COUNTIFS($E$4:$F$23,Q13) -> 1 | V13: =COUNTIFS($G$4:$H$23,Q13) -> 0 | W13: =COUNTIFS($I$4:$I$23,Q13) -> 1 | X13: =COUNTIFS($J$4:$K$23,Q13) -> 0 | Y13: =COUNTIFS($L$4:$L$23,Q13) -> 1 | Z13: =COUNTIFS($M$4:$N$23,Q13) -> 1 | AA13: =COUNTIFS($O$4:$O$23,Q13) -> 0 | AC13: 高二10班 | AD13: 41 | AE13: 0 | AF13: 41 | AG13: 41 | AH13: 0 | AI13: 0 | AK13: 物理学考20考场 | AL13: 20*45 | AM13: =20*45 -> 900 | AN13: 50 | AO13: =AM13+AN13 -> 950
A14: 高二11班 | B14: =COUNTIFS(学生编排结果!$H:$H,A14) -> 42 | C14: 郑婉慧 | D14: 贺育林 | E14: 郑婉慧 | F14: 陈晓迪 | G14: 李镇国 | H14: 王昕 | I14: 刘良桂 | J14: 陈晓迪 | K14: 范南莺 | L14: 彭海影 | M14: 陈映儿 | N14: 林蕴瑜 | O14: 彭海影 | Q14: 刘良桂 | R14: =COUNTIFS($C$4:$O$23,Q14) -> 5 | S14: =+T14*150+U14*75+V14*120+W14*60+X14*165+Y14*60+Z14*120+AA14*60 -> 435 | T14: =COUNTIFS($C$4:$D$23,Q14) -> 0 | U14: =COUNTIFS($E$4:$F$23,Q14) -> 1 | V14: =COUNTIFS($G$4:$H$23,Q14) -> 1 | W14: =COUNTIFS($I$4:$I$23,Q14) -> 1 | X14: =COUNTIFS($J$4:$K$23,Q14) -> 0 | Y14: =COUNTIFS($L$4:$L$23,Q14) -> 1 | Z14: =COUNTIFS($M$4:$N$23,Q14) -> 1 | AA14: =COUNTIFS($O$4:$O$23,Q14) -> 0 | AC14: 高二11班 | AD14: 42 | AE14: 0 | AF14: 42 | AG14: 42 | AH14: 0 | AI14: 0 | AK14: 政治学考20考场 | AL14: 20*45 | AM14: =20*45 -> 900 | AN14: 50 | AO14: =AM14+AN14 -> 950
A15: 高二12班 | B15: =COUNTIFS(学生编排结果!$H:$H,A15) -> 42 | C15: 黄楚琪 | E15: 张妮 | G15: 吕雪容 | I15: 贺育林 | J15: 钟三明 | L15: 王昕 | M15: 彭海影 | O15: 张妮 | Q15: 贺育林 | R15: =COUNTIFS($C$4:$O$23,Q15) -> 5 | S15: =+T15*150+U15*75+V15*120+W15*60+X15*165+Y15*60+Z15*120+AA15*60 -> 465 | T15: =COUNTIFS($C$4:$D$23,Q15) -> 1 | U15: =COUNTIFS($E$4:$F$23,Q15) -> 1 | V15: =COUNTIFS($G$4:$H$23,Q15) -> 1 | W15: =COUNTIFS($I$4:$I$23,Q15) -> 1 | X15: =COUNTIFS($J$4:$K$23,Q15) -> 0 | Y15: =COUNTIFS($L$4:$L$23,Q15) -> 1 | Z15: =COUNTIFS($M$4:$N$23,Q15) -> 0 | AA15: =COUNTIFS($O$4:$O$23,Q15) -> 0 | AC15: 高二12班 | AD15: 42 | AE15: 0 | AF15: 42 | AG15: 0 | AH15: 42 | AI15: 0
A16: 高二13班 | B16: =COUNTIFS(学生编排结果!$H:$H,A16) -> 42 | C16: 蒋红 | D16: 孙静 | E16: 张莉萍 | F16: 蒋思明 | G16: 李昕雨 | H16: 陈映儿 | I16: 黄楚琪 | J16: 王玉发 | K16: 刘小洪 | L16: 赵香甜 | M16: 张光礼 | N16: 赵香甜 | O16: 周罗洁 | Q16: 黄楚琪 | R16: =COUNTIFS($C$4:$O$23,Q16) -> 5 | S16: =+T16*150+U16*75+V16*120+W16*60+X16*165+Y16*60+Z16*120+AA16*60 -> 465 | T16: =COUNTIFS($C$4:$D$23,Q16) -> 1 | U16: =COUNTIFS($E$4:$F$23,Q16) -> 1 | V16: =COUNTIFS($G$4:$H$23,Q16) -> 1 | W16: =COUNTIFS($I$4:$I$23,Q16) -> 1 | X16: =COUNTIFS($J$4:$K$23,Q16) -> 0 | Y16: =COUNTIFS($L$4:$L$23,Q16) -> 1 | Z16: =COUNTIFS($M$4:$N$23,Q16) -> 0 | AA16: =COUNTIFS($O$4:$O$23,Q16) -> 0 | AC16: 高二13班 | AD16: 42 | AE16: 0 | AF16: 42 | AG16: 0 | AH16: 42 | AI16: 0
A17: 高二14班 | B17: =COUNTIFS(学生编排结果!$H:$H,A17) -> 42 | C17: 张芷欣 | E17: 吕雪容 | G17: 王菲飞 | I17: 蒋虹 | J17: 张芷欣 | L17: 段蕴瑶 | M17: 段蕴瑶 | O17: 李镇国 | Q17: 许业琳 | R17: =COUNTIFS($C$4:$O$23,Q17) -> 5 | S17: =+T17*150+U17*75+V17*120+W17*60+X17*165+Y17*60+Z17*120+AA17*60 -> 435 | T17: =COUNTIFS($C$4:$D$23,Q17) -> 0 | U17: =COUNTIFS($E$4:$F$23,Q17) -> 1 | V17: =COUNTIFS($G$4:$H$23,Q17) -> 1 | W17: =COUNTIFS($I$4:$I$23,Q17) -> 0 | X17: =COUNTIFS($J$4:$K$23,Q17) -> 0 | Y17: =COUNTIFS($L$4:$L$23,Q17) -> 1 | Z17: =COUNTIFS($M$4:$N$23,Q17) -> 1 | AA17: =COUNTIFS($O$4:$O$23,Q17) -> 1 | AC17: 高二14班 | AD17: 42 | AE17: 0 | AF17: 42 | AG17: 0 | AH17: 0 | AI17: 42
A18: 高二15班 | B18: =COUNTIFS(学生编排结果!$H:$H,A18) -> 42 | C18: 侯文娟 | D18: 刘艳 | E18: 孙静 | F18: 张光礼 | G18: 梁洁楹 | H18: 陈美苑 | I18: 张芷欣 | J18: 钟日明 | K18: 张玉静 | L18: 张妮 | M18: 钟三明 | N18: 曹芳 | O18: 陈坚 | Q18: 陈坚 | R18: =COUNTIFS($C$4:$O$23,Q18) -> 4 | S18: =+T18*150+U18*75+V18*120+W18*60+X18*165+Y18*60+Z18*120+AA18*60 -> 465 | T18: =COUNTIFS($C$4:$D$23,Q18) -> 0 | U18: =COUNTIFS($E$4:$F$23,Q18) -> 0 | V18: =COUNTIFS($G$4:$H$23,Q18) -> 1 | W18: =COUNTIFS($I$4:$I$23,Q18) -> 0 | X18: =COUNTIFS($J$4:$K$23,Q18) -> 1 | Y18: =COUNTIFS($L$4:$L$23,Q18) -> 0 | Z18: =COUNTIFS($M$4:$N$23,Q18) -> 1 | AA18: =COUNTIFS($O$4:$O$23,Q18) -> 1 | AC18: 高二15班 | AD18: 0 | AE18: 42 | AF18: 0 | AG18: 0 | AH18: 42 | AI18: 42
A19: 高二16班 | B19: =COUNTIFS(学生编排结果!$H:$H,A19) -> 42 | C19: 李智芳 | E19: 赵香甜 | G19: 蒋虹 | I19: 谢晨阳 | J19: 陈坚 | L19: 曹芳 | M19: 刘良桂 | O19: 王玉发 | Q19: 郑婉慧 | R19: =COUNTIFS($C$4:$O$23,Q19) -> 4 | S19: =+T19*150+U19*75+V19*120+W19*60+X19*165+Y19*60+Z19*120+AA19*60 -> 465 | T19: =COUNTIFS($C$4:$D$23,Q19) -> 1 | U19: =COUNTIFS($E$4:$F$23,Q19) -> 1 | V19: =COUNTIFS($G$4:$H$23,Q19) -> 1 | W19: =COUNTIFS($I$4:$I$23,Q19) -> 0 | X19: =COUNTIFS($J$4:$K$23,Q19) -> 0 | Y19: =COUNTIFS($L$4:$L$23,Q19) -> 0 | Z19: =COUNTIFS($M$4:$N$23,Q19) -> 1 | AA19: =COUNTIFS($O$4:$O$23,Q19) -> 0 | AC19: 高二16班 | AD19: 0 | AE19: 42 | AF19: 0 | AG19: 0 | AH19: 42 | AI19: 42
A20: 公共课室3 | B20: =COUNTIFS(学生编排结果!$H:$H,A20) -> 42 | C20: 王帅 | D20: 张馨予 | E20: 段蕴瑶 | F20: 曹芳 | G20: 张芷欣 | H20: 侯文娟 | I20: 王帅 | J20: 黄朝阳 | K20: 周罗洁 | L20: 刘良桂 | M20: 梁洁楹 | N20: 陈美苑 | O20: 刘小洪 | Q20: 周罗洁 | R20: =COUNTIFS($C$4:$O$23,Q20) -> 4 | S20: =+T20*150+U20*75+V20*120+W20*60+X20*165+Y20*60+Z20*120+AA20*60 -> 495 | T20: =COUNTIFS($C$4:$D$23,Q20) -> 1 | U20: =COUNTIFS($E$4:$F$23,Q20) -> 0 | V20: =COUNTIFS($G$4:$H$23,Q20) -> 0 | W20: =COUNTIFS($I$4:$I$23,Q20) -> 0 | X20: =COUNTIFS($J$4:$K$23,Q20) -> 1 | Y20: =COUNTIFS($L$4:$L$23,Q20) -> 0 | Z20: =COUNTIFS($M$4:$N$23,Q20) -> 1 | AA20: =COUNTIFS($O$4:$O$23,Q20) -> 1 | AC20: 公共课室3 | AD20: 0 | AE20: 42 | AF20: 0 | AG20: 0 | AH20: 42 | AI20: 42
A21: 公共课室4 | B21: =COUNTIFS(学生编排结果!$H:$H,A21) -> 42 | C21: 彭海影 | E21: 刘良桂 | G21: 刘艳 | I21: 王昕 | J21: 王昕 | L21: 贺育林 | M21: 蒋虹 | O21: 蒋红 | Q21: 王昕 | R21: =COUNTIFS($C$4:$O$23,Q21) -> 5 | S21: =+T21*150+U21*75+V21*120+W21*60+X21*165+Y21*60+Z21*120+AA21*60 -> 480 | T21: =COUNTIFS($C$4:$D$23,Q21) -> 0 | U21: =COUNTIFS($E$4:$F$23,Q21) -> 1 | V21: =COUNTIFS($G$4:$H$23,Q21) -> 1 | W21: =COUNTIFS($I$4:$I$23,Q21) -> 1 | X21: =COUNTIFS($J$4:$K$23,Q21) -> 1 | Y21: =COUNTIFS($L$4:$L$23,Q21) -> 1 | Z21: =COUNTIFS($M$4:$N$23,Q21) -> 0 | AA21: =COUNTIFS($O$4:$O$23,Q21) -> 0 | AC21: 公共课室4 | AD21: 0 | AE21: 42 | AF21: 0 | AG21: 0 | AH21: 42 | AI21: 42
A22: 公共课室5 | B22: =COUNTIFS(学生编排结果!$H:$H,A22) -> 36 | C22: 明珊珊 | D22: 李嘉燕 | E22: 黄朝阳 | F22: 侯文娟 | G22: 李智芳 | H22: 蒋思明 | I22: 王海劲 | J22: 王海劲 | K22: 李镇国 | L22: 黄楚琪 | M22: 陈坚 | N22: 郑婉慧 | O22: 钟日明 | Q22: 王海劲 | R22: =COUNTIFS($C$4:$O$23,Q22) -> 4 | S22: =+T22*150+U22*75+V22*120+W22*60+X22*165+Y22*60+Z22*120+AA22*60 -> 450 | T22: =COUNTIFS($C$4:$D$23,Q22) -> 1 | U22: =COUNTIFS($E$4:$F$23,Q22) -> 1 | V22: =COUNTIFS($G$4:$H$23,Q22) -> 0 | W22: =COUNTIFS($I$4:$I$23,Q22) -> 1 | X22: =COUNTIFS($J$4:$K$23,Q22) -> 1 | Y22: =COUNTIFS($L$4:$L$23,Q22) -> 0 | Z22: =COUNTIFS($M$4:$N$23,Q22) -> 0 | AA22: =COUNTIFS($O$4:$O$23,Q22) -> 0 | AC22: 公共课室5 | AD22: 37 (1-37) | AE22: 0 | AF22: 34(1-33、37) | AG22: 8 (29-36) | AH22: 19 (1-17、34-35) | AI22: 13 (18-28、36-37)
A23: 公共课室6 | B23: =COUNTIFS(学生编排结果!$H:$H,A23) -> 25 | C23: 王海劲 | E23: 刘艳 | G23: 王帅 | I23: 李镇国 | J23: 马嘉骏 | L23: 许业琳 | M23: 周罗洁 | O23: 张玉静 | Q23: 李镇国 | R23: =COUNTIFS($C$4:$O$23,Q23) -> 5 | S23: =+T23*150+U23*75+V23*120+W23*60+X23*165+Y23*60+Z23*120+AA23*60 -> 480 | T23: =COUNTIFS($C$4:$D$23,Q23) -> 0 | U23: =COUNTIFS($E$4:$F$23,Q23) -> 1 | V23: =COUNTIFS($G$4:$H$23,Q23) -> 1 | W23: =COUNTIFS($I$4:$I$23,Q23) -> 1 | X23: =COUNTIFS($J$4:$K$23,Q23) -> 1 | Y23: =COUNTIFS($L$4:$L$23,Q23) -> 0 | Z23: =COUNTIFS($M$4:$N$23,Q23) -> 0 | AA23: =COUNTIFS($O$4:$O$23,Q23) -> 1 | AC23: 公共课室6 | AD23: 0 | AE23: 25 (1-25) | AF23: 1 (25) | AG23: 9 (16-24) | AH23: 18 (1-15、22-24) | AI23: 22 (1-21、25)
A24: 考务室：三楼报告厅1 提前30分钟到考务室签到 | Q24: 马嘉骏 | R24: =COUNTIFS($C$4:$O$23,Q24) -> 4 | S24: =+T24*150+U24*75+V24*120+W24*60+X24*165+Y24*60+Z24*120+AA24*60 -> 450 | T24: =COUNTIFS($C$4:$D$23,Q24) -> 1 | U24: =COUNTIFS($E$4:$F$23,Q24) -> 1 | V24: =COUNTIFS($G$4:$H$23,Q24) -> 0 | W24: =COUNTIFS($I$4:$I$23,Q24) -> 0 | X24: =COUNTIFS($J$4:$K$23,Q24) -> 1 | Y24: =COUNTIFS($L$4:$L$23,Q24) -> 0 | Z24: =COUNTIFS($M$4:$N$23,Q24) -> 0 | AA24: =COUNTIFS($O$4:$O$23,Q24) -> 1 | AC24: 总计 | AD24: 624 | AE24: 193 | AF24: 622 | AG24: 479 | AH24: 289 | AI24: 244
Q25: 陈映儿 | R25: =COUNTIFS($C$4:$O$23,Q25) -> 4 | S25: =+T25*150+U25*75+V25*120+W25*60+X25*165+Y25*60+Z25*120+AA25*60 -> 465 | T25: =COUNTIFS($C$4:$D$23,Q25) -> 0 | U25: =COUNTIFS($E$4:$F$23,Q25) -> 0 | V25: =COUNTIFS($G$4:$H$23,Q25) -> 1 | W25: =COUNTIFS($I$4:$I$23,Q25) -> 0 | X25: =COUNTIFS($J$4:$K$23,Q25) -> 1 | Y25: =COUNTIFS($L$4:$L$23,Q25) -> 0 | Z25: =COUNTIFS($M$4:$N$23,Q25) -> 1 | AA25: =COUNTIFS($O$4:$O$23,Q25) -> 1
Q26: 王菲飞 | R26: =COUNTIFS($C$4:$O$23,Q26) -> 4 | S26: =+T26*150+U26*75+V26*120+W26*60+X26*165+Y26*60+Z26*120+AA26*60 -> 465 | T26: =COUNTIFS($C$4:$D$23,Q26) -> 0 | U26: =COUNTIFS($E$4:$F$23,Q26) -> 0 | V26: =COUNTIFS($G$4:$H$23,Q26) -> 1 | W26: =COUNTIFS($I$4:$I$23,Q26) -> 1 | X26: =COUNTIFS($J$4:$K$23,Q26) -> 1 | Y26: =COUNTIFS($L$4:$L$23,Q26) -> 0 | Z26: =COUNTIFS($M$4:$N$23,Q26) -> 1 | AA26: =COUNTIFS($O$4:$O$23,Q26) -> 0
Q27: 梁洁楹 | R27: =COUNTIFS($C$4:$O$23,Q27) -> 4 | S27: =+T27*150+U27*75+V27*120+W27*60+X27*165+Y27*60+Z27*120+AA27*60 -> 465 | T27: =COUNTIFS($C$4:$D$23,Q27) -> 0 | U27: =COUNTIFS($E$4:$F$23,Q27) -> 0 | V27: =COUNTIFS($G$4:$H$23,Q27) -> 1 | W27: =COUNTIFS($I$4:$I$23,Q27) -> 0 | X27: =COUNTIFS($J$4:$K$23,Q27) -> 1 | Y27: =COUNTIFS($L$4:$L$23,Q27) -> 0 | Z27: =COUNTIFS($M$4:$N$23,Q27) -> 1 | AA27: =COUNTIFS($O$4:$O$23,Q27) -> 1
Q28: 陈美苑 | R28: =COUNTIFS($C$4:$O$23,Q28) -> 4 | S28: =+T28*150+U28*75+V28*120+W28*60+X28*165+Y28*60+Z28*120+AA28*60 -> 465 | T28: =COUNTIFS($C$4:$D$23,Q28) -> 0 | U28: =COUNTIFS($E$4:$F$23,Q28) -> 0 | V28: =COUNTIFS($G$4:$H$23,Q28) -> 1 | W28: =COUNTIFS($I$4:$I$23,Q28) -> 1 | X28: =COUNTIFS($J$4:$K$23,Q28) -> 1 | Y28: =COUNTIFS($L$4:$L$23,Q28) -> 0 | Z28: =COUNTIFS($M$4:$N$23,Q28) -> 1 | AA28: =COUNTIFS($O$4:$O$23,Q28) -> 0 | AD28: 4选2考试顺序
Q29: 蒋虹 | R29: =COUNTIFS($C$4:$O$23,Q29) -> 4 | S29: =+T29*150+U29*75+V29*120+W29*60+X29*165+Y29*60+Z29*120+AA29*60 -> 465 | T29: =COUNTIFS($C$4:$D$23,Q29) -> 0 | U29: =COUNTIFS($E$4:$F$23,Q29) -> 0 | V29: =COUNTIFS($G$4:$H$23,Q29) -> 1 | W29: =COUNTIFS($I$4:$I$23,Q29) -> 1 | X29: =COUNTIFS($J$4:$K$23,Q29) -> 1 | Y29: =COUNTIFS($L$4:$L$23,Q29) -> 0 | Z29: =COUNTIFS($M$4:$N$23,Q29) -> 1 | AA29: =COUNTIFS($O$4:$O$23,Q29) -> 0
Q30: 余晓娜 | R30: =COUNTIFS($C$4:$O$23,Q30) -> 4 | S30: =+T30*150+U30*75+V30*120+W30*60+X30*165+Y30*60+Z30*120+AA30*60 -> 450 | T30: =COUNTIFS($C$4:$D$23,Q30) -> 1 | U30: =COUNTIFS($E$4:$F$23,Q30) -> 1 | V30: =COUNTIFS($G$4:$H$23,Q30) -> 0 | W30: =COUNTIFS($I$4:$I$23,Q30) -> 0 | X30: =COUNTIFS($J$4:$K$23,Q30) -> 1 | Y30: =COUNTIFS($L$4:$L$23,Q30) -> 0 | Z30: =COUNTIFS($M$4:$N$23,Q30) -> 0 | AA30: =COUNTIFS($O$4:$O$23,Q30) -> 1 | AF30: 第一段 | AH30: 第二段
Q31: 王倩 | R31: =COUNTIFS($C$4:$O$23,Q31) -> 4 | S31: =+T31*150+U31*75+V31*120+W31*60+X31*165+Y31*60+Z31*120+AA31*60 -> 450 | T31: =COUNTIFS($C$4:$D$23,Q31) -> 1 | U31: =COUNTIFS($E$4:$F$23,Q31) -> 1 | V31: =COUNTIFS($G$4:$H$23,Q31) -> 0 | W31: =COUNTIFS($I$4:$I$23,Q31) -> 0 | X31: =COUNTIFS($J$4:$K$23,Q31) -> 1 | Y31: =COUNTIFS($L$4:$L$23,Q31) -> 0 | Z31: =COUNTIFS($M$4:$N$23,Q31) -> 0 | AA31: =COUNTIFS($O$4:$O$23,Q31) -> 1 | AD31: 1-11班 | AF31: 化学 | AH31: 生物
Q32: 谢晨阳 | R32: =COUNTIFS($C$4:$O$23,Q32) -> 4 | S32: =+T32*150+U32*75+V32*120+W32*60+X32*165+Y32*60+Z32*120+AA32*60 -> 435 | T32: =COUNTIFS($C$4:$D$23,Q32) -> 1 | U32: =COUNTIFS($E$4:$F$23,Q32) -> 0 | V32: =COUNTIFS($G$4:$H$23,Q32) -> 0 | W32: =COUNTIFS($I$4:$I$23,Q32) -> 1 | X32: =COUNTIFS($J$4:$K$23,Q32) -> 1 | Y32: =COUNTIFS($L$4:$L$23,Q32) -> 0 | Z32: =COUNTIFS($M$4:$N$23,Q32) -> 0 | AA32: =COUNTIFS($O$4:$O$23,Q32) -> 1 | AD32: 12-13班 | AF32: 化学 | AH32: 地理
Q33: 范南莺 | R33: =COUNTIFS($C$4:$O$23,Q33) -> 4 | S33: =+T33*150+U33*75+V33*120+W33*60+X33*165+Y33*60+Z33*120+AA33*60 -> 495 | T33: =COUNTIFS($C$4:$D$23,Q33) -> 1 | U33: =COUNTIFS($E$4:$F$23,Q33) -> 0 | V33: =COUNTIFS($G$4:$H$23,Q33) -> 0 | W33: =COUNTIFS($I$4:$I$23,Q33) -> 0 | X33: =COUNTIFS($J$4:$K$23,Q33) -> 1 | Y33: =COUNTIFS($L$4:$L$23,Q33) -> 0 | Z33: =COUNTIFS($M$4:$N$23,Q33) -> 1 | AA33: =COUNTIFS($O$4:$O$23,Q33) -> 1 | AD33: 14班 | AF33: 化学 | AH33: 政治
Q34: 罗雯雯 | R34: 请假 | S34: =+T34*150+U34*75+V34*120+W34*60+X34*165+Y34*60+Z34*120+AA34*60 -> 0 | T34: =COUNTIFS($C$4:$D$23,Q34) -> 0 | U34: =COUNTIFS($E$4:$F$23,Q34) -> 0 | V34: =COUNTIFS($G$4:$H$23,Q34) -> 0 | W34: =COUNTIFS($I$4:$I$23,Q34) -> 0 | X34: =COUNTIFS($J$4:$K$23,Q34) -> 0 | Y34: =COUNTIFS($L$4:$L$23,Q34) -> 0 | Z34: =COUNTIFS($M$4:$N$23,Q34) -> 0 | AA34: =COUNTIFS($O$4:$O$23,Q34) -> 0 | AD34: 15-公共4 | AF34: 地理 | AH34: 政治
Q35: 张妮 | R35: =COUNTIFS($C$4:$O$23,Q35) -> 5 | S35: =+T35*150+U35*75+V35*120+W35*60+X35*165+Y35*60+Z35*120+AA35*60 -> 480 | T35: =COUNTIFS($C$4:$D$23,Q35) -> 0 | U35: =COUNTIFS($E$4:$F$23,Q35) -> 1 | V35: =COUNTIFS($G$4:$H$23,Q35) -> 1 | W35: =COUNTIFS($I$4:$I$23,Q35) -> 0 | X35: =COUNTIFS($J$4:$K$23,Q35) -> 1 | Y35: =COUNTIFS($L$4:$L$23,Q35) -> 1 | Z35: =COUNTIFS($M$4:$N$23,Q35) -> 0 | AA35: =COUNTIFS($O$4:$O$23,Q35) -> 1 | AD35: 公5 | AF35: 化学（1-33、37） 生物（34-36） | AH35: 地理（1-17、34-35） 政治（18-28、36-37） 生物（29-33）
Q36: 张莉萍 | R36: =COUNTIFS($C$4:$O$23,Q36) -> 4 | S36: =+T36*150+U36*75+V36*120+W36*60+X36*165+Y36*60+Z36*120+AA36*60 -> 450 | T36: =COUNTIFS($C$4:$D$23,Q36) -> 1 | U36: =COUNTIFS($E$4:$F$23,Q36) -> 1 | V36: =COUNTIFS($G$4:$H$23,Q36) -> 0 | W36: =COUNTIFS($I$4:$I$23,Q36) -> 0 | X36: =COUNTIFS($J$4:$K$23,Q36) -> 1 | Y36: =COUNTIFS($L$4:$L$23,Q36) -> 1 | Z36: =COUNTIFS($M$4:$N$23,Q36) -> 0 | AA36: =COUNTIFS($O$4:$O$23,Q36) -> 0
Q37: 陈晓迪 | R37: =COUNTIFS($C$4:$O$23,Q37) -> 3 | S37: =+T37*150+U37*75+V37*120+W37*60+X37*165+Y37*60+Z37*120+AA37*60 -> 360 | T37: =COUNTIFS($C$4:$D$23,Q37) -> 0 | U37: =COUNTIFS($E$4:$F$23,Q37) -> 1 | V37: =COUNTIFS($G$4:$H$23,Q37) -> 0 | W37: =COUNTIFS($I$4:$I$23,Q37) -> 0 | X37: =COUNTIFS($J$4:$K$23,Q37) -> 1 | Y37: =COUNTIFS($L$4:$L$23,Q37) -> 0 | Z37: =COUNTIFS($M$4:$N$23,Q37) -> 1 | AA37: =COUNTIFS($O$4:$O$23,Q37) -> 0
Q38: 黄朝阳 | R38: =COUNTIFS($C$4:$O$23,Q38) -> 4 | S38: =+T38*150+U38*75+V38*120+W38*60+X38*165+Y38*60+Z38*120+AA38*60 -> 480 | T38: =COUNTIFS($C$4:$D$23,Q38) -> 0 | U38: =COUNTIFS($E$4:$F$23,Q38) -> 1 | V38: =COUNTIFS($G$4:$H$23,Q38) -> 1 | W38: =COUNTIFS($I$4:$I$23,Q38) -> 0 | X38: =COUNTIFS($J$4:$K$23,Q38) -> 1 | Y38: =COUNTIFS($L$4:$L$23,Q38) -> 0 | Z38: =COUNTIFS($M$4:$N$23,Q38) -> 1 | AA38: =COUNTIFS($O$4:$O$23,Q38) -> 0 | AD38: 公6 | AF38: 地理（1-15） 生物（16-24） 化学（25） | AH38: 政治（1-21） 地理（22-24） 政治（25）
Q39: 杨眉 | R39: =COUNTIFS($C$4:$O$23,Q39) -> 4 | S39: =+T39*150+U39*75+V39*120+W39*60+X39*165+Y39*60+Z39*120+AA39*60 -> 450 | T39: =COUNTIFS($C$4:$D$23,Q39) -> 1 | U39: =COUNTIFS($E$4:$F$23,Q39) -> 1 | V39: =COUNTIFS($G$4:$H$23,Q39) -> 0 | W39: =COUNTIFS($I$4:$I$23,Q39) -> 0 | X39: =COUNTIFS($J$4:$K$23,Q39) -> 1 | Y39: =COUNTIFS($L$4:$L$23,Q39) -> 1 | Z39: =COUNTIFS($M$4:$N$23,Q39) -> 0 | AA39: =COUNTIFS($O$4:$O$23,Q39) -> 0
Q40: 王玉发 | R40: =COUNTIFS($C$4:$O$23,Q40) -> 4 | S40: =+T40*150+U40*75+V40*120+W40*60+X40*165+Y40*60+Z40*120+AA40*60 -> 465 | T40: =COUNTIFS($C$4:$D$23,Q40) -> 0 | U40: =COUNTIFS($E$4:$F$23,Q40) -> 0 | V40: =COUNTIFS($G$4:$H$23,Q40) -> 1 | W40: =COUNTIFS($I$4:$I$23,Q40) -> 0 | X40: =COUNTIFS($J$4:$K$23,Q40) -> 1 | Y40: =COUNTIFS($L$4:$L$23,Q40) -> 0 | Z40: =COUNTIFS($M$4:$N$23,Q40) -> 1 | AA40: =COUNTIFS($O$4:$O$23,Q40) -> 1
...

Sheet 监考安排（旧）
A1: =[1]巡视!$A$1&"监考安排" -> 2025-2026学年高二第一学期期中考监考安排 | T1: 11月5日（周三） | X1: 11月6日（周四）
A2: 试室 | B2: 人数 | C2: 11月5日（周三） | J2: 11月6日（周四） | T2: 语文 | U2: 物理/历史 | V2: 数学 | W2: 政治学考 | X2: 4选2 | Y2: 自习 | Z2: 英语 | AA2: 物理学考
C3: 8:00-10:30 语文 | E3: 11:00-12:15 物理/历史 | G3: 14:30-16:30 数学 | I3: 17:00-18:00 政治学考 | J3: 8:00-10:45 4选2 | L3: 11:15-12:15 自习 | M3: 14:30-16:30 英语 | O3: 17:00-18:00 物理学考 | Q3: 姓名 | R3: 段数 | S3: 时长 | T3: 8:00-10:30 | U3: 11:00-12:15 | V3: 14:30-16:30 | W3: 17:00-18:00 | X3: 8:00-10:45 | Y3: 11:15-12:15 | Z3: 14:30-16:30 | AA3: 17:00-18:00 | AD3: 物理 | AE3: 历史 | AF3: 化学 | AG3: 生物 | AH3: 地理 | AI3: 政治 | AK3: 语文20考场 | AL3: 20*45 | AM3: =20*45 -> 900 | AN3: 50 | AO3: =AM3+AN3 -> 950
A4: 高二1班 | B4: =COUNTIFS([1]学生编排结果!$H:$H,A4) -> 42 | C4: 蒋思明 | D4: 吕雪容 | E4: 杨眉 | F4: 张馨予 | G4: 陈晓迪 | H4: 黄朝阳 | I4: 林蕴瑜 | J4: 张莉萍 | K4: 杨眉 | L4: 杨眉 | M4: 陈晓迪 | N4: 黄朝阳 | O4: 马嘉骏 | Q4: 林蕴瑜 | R4: =COUNTIFS($C$4:$O$23,Q4) -> 5 | S4: =+T4*150+U4*75+V4*120+W4*60+X4*165+Y4*60+Z4*120+AA4*60 -> 435 | T4: =COUNTIFS($C$4:$D$23,Q4) -> 0 | U4: =COUNTIFS($E$4:$F$23,Q4) -> 1 | V4: =COUNTIFS($G$4:$H$23,Q4) -> 1 | W4: =COUNTIFS($I$4:$I$23,Q4) -> 1 | X4: =COUNTIFS($J$4:$K$23,Q4) -> 0 | Y4: =COUNTIFS($L$4:$L$23,Q4) -> 1 | Z4: =COUNTIFS($M$4:$N$23,Q4) -> 1 | AA4: =COUNTIFS($O$4:$O$23,Q4) -> 0 | AC4: 高二1班 | AD4: 42 | AE4: 0 | AF4: 42 | AG4: 42 | AH4: 0 | AI4: 0 | AK4: 数学20考场 | AL4: 20*45 | AM4: =20*45 -> 900 | AN4: 50 | AO4: =AM4+AN4 -> 950
A5: 高二2班 | B5: =COUNTIFS([1]学生编排结果!$H:$H,A5) -> 42 | C5: 李镇国 | E5: 李昕雨 | G5: 王玉发 | I5: 明珊珊 | J5: 余晓娜 | L5: 李智芳 | M5: 王玉发 | O5: 陈映儿 | Q5: 明珊珊 | R5: =COUNTIFS($C$4:$O$23,Q5) -> 5 | S5: =+T5*150+U5*75+V5*120+W5*60+X5*165+Y5*60+Z5*120+AA5*60 -> 435 | T5: =COUNTIFS($C$4:$D$23,Q5) -> 0 | U5: =COUNTIFS($E$4:$F$23,Q5) -> 1 | V5: =COUNTIFS($G$4:$H$23,Q5) -> 1 | W5: =COUNTIFS($I$4:$I$23,Q5) -> 1 | X5: =COUNTIFS($J$4:$K$23,Q5) -> 0 | Y5: =COUNTIFS($L$4:$L$23,Q5) -> 1 | Z5: =COUNTIFS($M$4:$N$23,Q5) -> 1 | AA5: =COUNTIFS($O$4:$O$23,Q5) -> 0 | AC5: 高二2班 | AD5: 42 | AE5: 0 | AF5: 42 | AG5: 42 | AH5: 0 | AI5: 0 | AK5: 英语20考场 | AL5: 20*45 | AM5: =20*45 -> 900 | AN5: 50 | AO5: =AM5+AN5 -> 950
A6: 高二3班 | B6: =COUNTIFS([1]学生编排结果!$H:$H,A6) -> 42 | C6: 马嘉骏 | D6: 张光礼 | E6: 王昕 | F6: 李嘉燕 | G6: 刘小洪 | H6: 蒋红 | I6: 蒋思明 | J6: 王倩 | K6: 谢晨阳 | L6: 张莉萍 | M6: 刘小洪 | N6: 蒋红 | O6: 王菲飞 | Q6: 蒋思明 | R6: =COUNTIFS($C$4:$O$23,Q6) -> 5 | S6: =+T6*150+U6*75+V6*120+W6*60+X6*165+Y6*60+Z6*120+AA6*60 -> 465 | T6: =COUNTIFS($C$4:$D$23,Q6) -> 1 | U6: =COUNTIFS($E$4:$F$23,Q6) -> 1 | V6: =COUNTIFS($G$4:$H$23,Q6) -> 1 | W6: =COUNTIFS($I$4:$I$23,Q6) -> 1 | X6: =COUNTIFS($J$4:$K$23,Q6) -> 0 | Y6: =COUNTIFS($L$4:$L$23,Q6) -> 1 | Z6: =COUNTIFS($M$4:$N$23,Q6) -> 0 | AA6: =COUNTIFS($O$4:$O$23,Q6) -> 0 | AC6: 高二3班 | AD6: 42 | AE6: 0 | AF6: 42 | AG6: 42 | AH6: 0 | AI6: 0 | AK6: 物理15考场 | AL6: 15*45 | AM6: =15*45 -> 675 | AN6: 50 | AO6: =AM6+AN6 -> 725
A7: 高二4班 | B7: =COUNTIFS([1]学生编排结果!$H:$H,A7) -> 42 | C7: 余晓娜 | E7: 王海劲 | G7: 钟日明 | I7: 吕雪容 | J7: 范南莺 | L7: 张馨予 | M7: 钟日明 | O7: 梁洁楹 | Q7: 吕雪容 | R7: =COUNTIFS($C$4:$O$23,Q7) -> 5 | S7: =+T7*150+U7*75+V7*120+W7*60+X7*165+Y7*60+Z7*120+AA7*60 -> 465 | T7: =COUNTIFS($C$4:$D$23,Q7) -> 1 | U7: =COUNTIFS($E$4:$F$23,Q7) -> 1 | V7: =COUNTIFS($G$4:$H$23,Q7) -> 1 | W7: =COUNTIFS($I$4:$I$23,Q7) -> 1 | X7: =COUNTIFS($J$4:$K$23,Q7) -> 0 | Y7: =COUNTIFS($L$4:$L$23,Q7) -> 1 | Z7: =COUNTIFS($M$4:$N$23,Q7) -> 0 | AA7: =COUNTIFS($O$4:$O$23,Q7) -> 0 | AC7: 高二4班 | AD7: 42 | AE7: 0 | AF7: 42 | AG7: 42 | AH7: 0 | AI7: 0 | AK7: 历史5考场 | AL7: 5*45 | AM7: =5*45 -> 225 | AN7: 25 | AO7: =AM7+AN7 -> 250
A8: 高二5班 | B8: =COUNTIFS([1]学生编排结果!$H:$H,A8) -> 42 | C8: 王倩 | D8: 谢晨阳 | E8: 李镇国 | F8: 马嘉骏 | G8: 钟三明 | H8: 张玉静 | I8: 彭海影 | J8: 张馨予 | K8: 李昕雨 | L8: 李昕雨 | M8: 张玉静 | N8: 孙静 | O8: 陈美苑 | Q8: 彭海影 | R8: =COUNTIFS($C$4:$O$23,Q8) -> 5 | S8: =+T8*150+U8*75+V8*120+W8*60+X8*165+Y8*60+Z8*120+AA8*60 -> 435 | T8: =COUNTIFS($C$4:$D$23,Q8) -> 0 | U8: =COUNTIFS($E$4:$F$23,Q8) -> 1 | V8: =COUNTIFS($G$4:$H$23,Q8) -> 1 | W8: =COUNTIFS($I$4:$I$23,Q8) -> 1 | X8: =COUNTIFS($J$4:$K$23,Q8) -> 0 | Y8: =COUNTIFS($L$4:$L$23,Q8) -> 1 | Z8: =COUNTIFS($M$4:$N$23,Q8) -> 1 | AA8: =COUNTIFS($O$4:$O$23,Q8) -> 0 | AC8: 高二5班 | AD8: 42 | AE8: 0 | AF8: 42 | AG8: 42 | AH8: 0 | AI8: 0 | AK8: 化学16考场 | AL8: 16*45 | AM8: =16*45 -> 720 | AN8: 0 | AO8: =AM8+AN8 -> 720
A9: 高二6班 | B9: =COUNTIFS([1]学生编排结果!$H:$H,A9) -> 42 | C9: 范南莺 | E9: 林蕴瑜 | G9: 孙静 | I9: 张光礼 | J9: 李嘉燕 | L9: 李嘉燕 | M9: 张芷欣 | O9: 蒋虹 | Q9: 张光礼 | R9: =COUNTIFS($C$4:$O$23,Q9) -> 5 | S9: =+T9*150+U9*75+V9*120+W9*60+X9*165+Y9*60+Z9*120+AA9*60 -> 465 | T9: =COUNTIFS($C$4:$D$23,Q9) -> 1 | U9: =COUNTIFS($E$4:$F$23,Q9) -> 1 | V9: =COUNTIFS($G$4:$H$23,Q9) -> 0 | W9: =COUNTIFS($I$4:$I$23,Q9) -> 1 | X9: =COUNTIFS($J$4:$K$23,Q9) -> 0 | Y9: =COUNTIFS($L$4:$L$23,Q9) -> 1 | Z9: =COUNTIFS($M$4:$N$23,Q9) -> 1 | AA9: =COUNTIFS($O$4:$O$23,Q9) -> 0 | AC9: 高二6班 | AD9: 42 | AE9: 0 | AF9: 42 | AG9: 42 | AH9: 0 | AI9: 0 | AK9: 生物12考场 | AL9: 12*45 | AM9: =12*45 -> 540 | AN9: 0 | AO9: =AM9+AN9 -> 540
A10: 高二7班 | B10: =COUNTIFS([1]学生编排结果!$H:$H,A10) -> 42 | C10: 张妮 | D10: 张莉萍 | E10: 明珊珊 | F10: 贺育林 | G10: 贺育林 | H10: 黄楚琪 | I10: 赵香甜 | J10: 陈映儿 | K10: 王菲飞 | L10: 林蕴瑜 | M10: 侯文娟 | N10: 刘艳 | O10: 余晓娜 | Q10: 赵香甜 | R10: =COUNTIFS($C$4:$O$23,Q10) -> 5 | S10: =+T10*150+U10*75+V10*120+W10*60+X10*165+Y10*60+Z10*120+AA10*60 -> 465 | T10: =COUNTIFS($C$4:$D$23,Q10) -> 1 | U10: =COUNTIFS($E$4:$F$23,Q10) -> 1 | V10: =COUNTIFS($G$4:$H$23,Q10) -> 0 | W10: =COUNTIFS($I$4:$I$23,Q10) -> 1 | X10: =COUNTIFS($J$4:$K$23,Q10) -> 0 | Y10: =COUNTIFS($L$4:$L$23,Q10) -> 1 | Z10: =COUNTIFS($M$4:$N$23,Q10) -> 1 | AA10: =COUNTIFS($O$4:$O$23,Q10) -> 0 | AC10: 高二7班 | AD10: 42 | AE10: 0 | AF10: 42 | AG10: 42 | AH10: 0 | AI10: 0 | AK10: 地理8考场 | AL10: 8*45 | AM10: =8*45 -> 360 | AN10: 0 | AO10: =AM10+AN10 -> 360
A11: 高二8班 | B11: =COUNTIFS([1]学生编排结果!$H:$H,A11) -> 42 | C11: 赵香甜 | E11: 黄楚琪 | G11: 许业琳 | I11: 段蕴瑶 | J11: 张妮 | L11: 明珊珊 | M11: 李智芳 | O11: 王倩 | Q11: 段蕴瑶 | R11: =COUNTIFS($C$4:$O$23,Q11) -> 5 | S11: =+T11*150+U11*75+V11*120+W11*60+X11*165+Y11*60+Z11*120+AA11*60 -> 465 | T11: =COUNTIFS($C$4:$D$23,Q11) -> 1 | U11: =COUNTIFS($E$4:$F$23,Q11) -> 1 | V11: =COUNTIFS($G$4:$H$23,Q11) -> 0 | W11: =COUNTIFS($I$4:$I$23,Q11) -> 1 | X11: =COUNTIFS($J$4:$K$23,Q11) -> 0 | Y11: =COUNTIFS($L$4:$L$23,Q11) -> 1 | Z11: =COUNTIFS($M$4:$N$23,Q11) -> 1 | AA11: =COUNTIFS($O$4:$O$23,Q11) -> 0 | AC11: 高二8班 | AD11: 42 | AE11: 0 | AF11: 42 | AG11: 42 | AH11: 0 | AI11: 0 | AK11: 政治7考场 | AL11: 7*45 | AM11: =7*45 -> 315 | AO11: =AM11+AN11 -> 315
A12: 高二9班 | B12: =COUNTIFS([1]学生编排结果!$H:$H,A12) -> 42 | C12: 段蕴瑶 | D12: 杨眉 | E12: 许业琳 | F12: 余晓娜 | G12: 陈坚 | H12: 郑婉慧 | I12: 钟三明 | J12: 梁洁楹 | K12: 陈美苑 | L12: 蒋思明 | M12: 王菲飞 | N12: 王帅 | O12: 谢晨阳 | Q12: 钟三明 | R12: =COUNTIFS($C$4:$O$23,Q12) -> 4 | S12: =+T12*150+U12*75+V12*120+W12*60+X12*165+Y12*60+Z12*120+AA12*60 -> 465 | T12: =COUNTIFS($C$4:$D$23,Q12) -> 0 | U12: =COUNTIFS($E$4:$F$23,Q12) -> 0 | V12: =COUNTIFS($G$4:$H$23,Q12) -> 1 | W12: =COUNTIFS($I$4:$I$23,Q12) -> 1 | X12: =COUNTIFS($J$4:$K$23,Q12) -> 1 | Y12: =COUNTIFS($L$4:$L$23,Q12) -> 0 | Z12: =COUNTIFS($M$4:$N$23,Q12) -> 1 | AA12: =COUNTIFS($O$4:$O$23,Q12) -> 0 | AC12: 高二9班 | AD12: 42 | AE12: 0 | AF12: 42 | AG12: 42 | AH12: 0 | AI12: 0
A13: 高二10班 | B13: =COUNTIFS([1]学生编排结果!$H:$H,A13) -> 42 | C13: 曹芳 | E13: 王倩 | G13: 周罗洁 | I13: 曹芳 | J13: 蒋虹 | L13: 吕雪容 | M13: 明珊珊 | O13: 范南莺 | Q13: 曹芳 | R13: =COUNTIFS($C$4:$O$23,Q13) -> 5 | S13: =+T13*150+U13*75+V13*120+W13*60+X13*165+Y13*60+Z13*120+AA13*60 -> 465 | T13: =COUNTIFS($C$4:$D$23,Q13) -> 1 | U13: =COUNTIFS($E$4:$F$23,Q13) -> 1 | V13: =COUNTIFS($G$4:$H$23,Q13) -> 0 | W13: =COUNTIFS($I$4:$I$23,Q13) -> 1 | X13: =COUNTIFS($J$4:$K$23,Q13) -> 0 | Y13: =COUNTIFS($L$4:$L$23,Q13) -> 1 | Z13: =COUNTIFS($M$4:$N$23,Q13) -> 1 | AA13: =COUNTIFS($O$4:$O$23,Q13) -> 0 | AC13: 高二10班 | AD13: 42 | AE13: 0 | AF13: 42 | AG13: 42 | AH13: 0 | AI13: 0 | AK13: 物理学考20考场 | AL13: 20*45 | AM13: =20*45 -> 900 | AN13: 50 | AO13: =AM13+AN13 -> 950
A14: 高二11班 | B14: =COUNTIFS([1]学生编排结果!$H:$H,A14) -> 42 | C14: 刘良桂 | D14: 贺育林 | E14: 谢晨阳 | F14: 范南莺 | G14: 林蕴瑜 | H14: 明珊珊 | I14: 刘良桂 | J14: 陈晓迪 | K14: 黄朝阳 | L14: 彭海影 | M14: 陈映儿 | N14: 林蕴瑜 | O14: 孙静 | Q14: 刘良桂 | R14: =COUNTIFS($C$4:$O$23,Q14) -> 5 | S14: =+T14*150+U14*75+V14*120+W14*60+X14*165+Y14*60+Z14*120+AA14*60 -> 465 | T14: =COUNTIFS($C$4:$D$23,Q14) -> 1 | U14: =COUNTIFS($E$4:$F$23,Q14) -> 1 | V14: =COUNTIFS($G$4:$H$23,Q14) -> 0 | W14: =COUNTIFS($I$4:$I$23,Q14) -> 1 | X14: =COUNTIFS($J$4:$K$23,Q14) -> 0 | Y14: =COUNTIFS($L$4:$L$23,Q14) -> 1 | Z14: =COUNTIFS($M$4:$N$23,Q14) -> 1 | AA14: =COUNTIFS($O$4:$O$23,Q14) -> 0 | AC14: 高二11班 | AD14: 42 | AE14: 0 | AF14: 42 | AG14: 42 | AH14: 0 | AI14: 0 | AK14: 政治学考20考场 | AL14: 20*45 | AM14: =20*45 -> 900 | AN14: 50 | AO14: =AM14+AN14 -> 950
A15: 高二12班 | B15: =COUNTIFS([1]学生编排结果!$H:$H,A15) -> 42 | C15: 黄楚琪 | E15: 张妮 | G15: 吕雪容 | I15: 贺育林 | J15: 钟三明 | L15: 张光礼 | M15: 彭海影 | O15: 张妮 | Q15: 贺育林 | R15: =COUNTIFS($C$4:$O$23,Q15) -> 5 | S15: =+T15*150+U15*75+V15*120+W15*60+X15*165+Y15*60+Z15*120+AA15*60 -> 465 | T15: =COUNTIFS($C$4:$D$23,Q15) -> 1 | U15: =COUNTIFS($E$4:$F$23,Q15) -> 1 | V15: =COUNTIFS($G$4:$H$23,Q15) -> 1 | W15: =COUNTIFS($I$4:$I$23,Q15) -> 1 | X15: =COUNTIFS($J$4:$K$23,Q15) -> 0 | Y15: =COUNTIFS($L$4:$L$23,Q15) -> 1 | Z15: =COUNTIFS($M$4:$N$23,Q15) -> 0 | AA15: =COUNTIFS($O$4:$O$23,Q15) -> 0 | AC15: 高二12班 | AD15: 42 | AE15: 0 | AF15: 42 | AG15: 0 | AH15: 42 | AI15: 0
A16: 高二13班 | B16: =COUNTIFS([1]学生编排结果!$H:$H,A16) -> 42 | C16: 许业琳 | D16: 孙静 | E16: 张莉萍 | F16: 蒋思明 | G16: 彭海影 | H16: 陈映儿 | I16: 黄楚琪 | J16: 王玉发 | K16: 刘小洪 | L16: 赵香甜 | M16: 张光礼 | N16: 赵香甜 | O16: 王帅 | Q16: 黄楚琪 | R16: =COUNTIFS($C$4:$O$23,Q16) -> 5 | S16: =+T16*150+U16*75+V16*120+W16*60+X16*165+Y16*60+Z16*120+AA16*60 -> 465 | T16: =COUNTIFS($C$4:$D$23,Q16) -> 1 | U16: =COUNTIFS($E$4:$F$23,Q16) -> 1 | V16: =COUNTIFS($G$4:$H$23,Q16) -> 1 | W16: =COUNTIFS($I$4:$I$23,Q16) -> 1 | X16: =COUNTIFS($J$4:$K$23,Q16) -> 0 | Y16: =COUNTIFS($L$4:$L$23,Q16) -> 1 | Z16: =COUNTIFS($M$4:$N$23,Q16) -> 0 | AA16: =COUNTIFS($O$4:$O$23,Q16) -> 0 | AC16: 高二13班 | AD16: 42 | AE16: 0 | AF16: 42 | AG16: 0 | AH16: 42 | AI16: 0
A17: 高二14班 | B17: =COUNTIFS([1]学生编排结果!$H:$H,A17) -> 42 | C17: 张芷欣 | E17: 吕雪容 | G17: 王菲飞 | I17: 许业琳 | J17: 蒋红 | L17: 段蕴瑶 | M17: 段蕴瑶 | O17: 陈晓迪 | Q17: 许业琳 | R17: =COUNTIFS($C$4:$O$23,Q17) -> 5 | S17: =+T17*150+U17*75+V17*120+W17*60+X17*165+Y17*60+Z17*120+AA17*60 -> 465 | T17: =COUNTIFS($C$4:$D$23,Q17) -> 1 | U17: =COUNTIFS($E$4:$F$23,Q17) -> 1 | V17: =COUNTIFS($G$4:$H$23,Q17) -> 1 | W17: =COUNTIFS($I$4:$I$23,Q17) -> 1 | X17: =COUNTIFS($J$4:$K$23,Q17) -> 0 | Y17: =COUNTIFS($L$4:$L$23,Q17) -> 1 | Z17: =COUNTIFS($M$4:$N$23,Q17) -> 0 | AA17: =COUNTIFS($O$4:$O$23,Q17) -> 0 | AC17: 高二14班 | AD17: 42 | AE17: 0 | AF17: 42 | AG17: 0 | AH17: 0 | AI17: 42
A18: 高二15班 | B18: =COUNTIFS([1]学生编排结果!$H:$H,A18) -> 42 | C18: 侯文娟 | D18: 刘艳 | E18: 彭海影 | F18: 张光礼 | G18: 梁洁楹 | H18: 陈美苑 | I18: 陈坚 | J18: 钟日明 | K18: 张玉静 | L18: 张妮 | M18: 钟三明 | N18: 曹芳 | O18: 黄朝阳 | Q18: 陈坚 | R18: =COUNTIFS($C$4:$O$23,Q18) -> 4 | S18: =+T18*150+U18*75+V18*120+W18*60+X18*165+Y18*60+Z18*120+AA18*60 -> 465 | T18: =COUNTIFS($C$4:$D$23,Q18) -> 0 | U18: =COUNTIFS($E$4:$F$23,Q18) -> 0 | V18: =COUNTIFS($G$4:$H$23,Q18) -> 1 | W18: =COUNTIFS($I$4:$I$23,Q18) -> 1 | X18: =COUNTIFS($J$4:$K$23,Q18) -> 1 | Y18: =COUNTIFS($L$4:$L$23,Q18) -> 0 | Z18: =COUNTIFS($M$4:$N$23,Q18) -> 1 | AA18: =COUNTIFS($O$4:$O$23,Q18) -> 0 | AC18: 高二15班 | AD18: 0 | AE18: 42 | AF18: 0 | AG18: 0 | AH18: 42 | AI18: 42
A19: 高二16班 | B19: =COUNTIFS([1]学生编排结果!$H:$H,A19) -> 42 | C19: 李智芳 | E19: 赵香甜 | G19: 蒋虹 | I19: 郑婉慧 | J19: 陈坚 | L19: 曹芳 | M19: 刘良桂 | O19: 王玉发 | Q19: 郑婉慧 | R19: =COUNTIFS($C$4:$O$23,Q19) -> 4 | S19: =+T19*150+U19*75+V19*120+W19*60+X19*165+Y19*60+Z19*120+AA19*60 -> 465 | T19: =COUNTIFS($C$4:$D$23,Q19) -> 0 | U19: =COUNTIFS($E$4:$F$23,Q19) -> 0 | V19: =COUNTIFS($G$4:$H$23,Q19) -> 1 | W19: =COUNTIFS($I$4:$I$23,Q19) -> 1 | X19: =COUNTIFS($J$4:$K$23,Q19) -> 1 | Y19: =COUNTIFS($L$4:$L$23,Q19) -> 0 | Z19: =COUNTIFS($M$4:$N$23,Q19) -> 1 | AA19: =COUNTIFS($O$4:$O$23,Q19) -> 0 | AC19: 高二16班 | AD19: 0 | AE19: 42 | AF19: 0 | AG19: 0 | AH19: 42 | AI19: 42
A20: 公共课室3 | B20: =COUNTIFS([1]学生编排结果!$H:$H,A20) -> 42 | C20: 王帅 | D20: 张馨予 | E20: 段蕴瑶 | F20: 曹芳 | G20: 张芷欣 | H20: 侯文娟 | I20: 周罗洁 | J20: 郑婉慧 | K20: 周罗洁 | L20: 刘良桂 | M20: 梁洁楹 | N20: 陈美苑 | O20: 刘小洪 | Q20: 周罗洁 | R20: =COUNTIFS($C$4:$O$23,Q20) -> 4 | S20: =+T20*150+U20*75+V20*120+W20*60+X20*165+Y20*60+Z20*120+AA20*60 -> 465 | T20: =COUNTIFS($C$4:$D$23,Q20) -> 0 | U20: =COUNTIFS($E$4:$F$23,Q20) -> 0 | V20: =COUNTIFS($G$4:$H$23,Q20) -> 1 | W20: =COUNTIFS($I$4:$I$23,Q20) -> 1 | X20: =COUNTIFS($J$4:$K$23,Q20) -> 1 | Y20: =COUNTIFS($L$4:$L$23,Q20) -> 0 | Z20: =COUNTIFS($M$4:$N$23,Q20) -> 1 | AA20: =COUNTIFS($O$4:$O$23,Q20) -> 0 | AC20: 公共课室3 | AD20: 0 | AE20: 42 | AF20: 0 | AG20: 0 | AH20: 42 | AI20: 42
A21: 公共课室4 | B21: =COUNTIFS([1]学生编排结果!$H:$H,A21) -> 42 | C21: 李昕雨 | E21: 刘良桂 | G21: 刘艳 | I21: 王昕 | J21: 王昕 | L21: 贺育林 | M21: 蒋虹 | O21: 蒋红 | Q21: 王昕 | R21: =COUNTIFS($C$4:$O$23,Q21) -> 4 | S21: =+T21*150+U21*75+V21*120+W21*60+X21*165+Y21*60+Z21*120+AA21*60 -> 450 | T21: =COUNTIFS($C$4:$D$23,Q21) -> 1 | U21: =COUNTIFS($E$4:$F$23,Q21) -> 1 | V21: =COUNTIFS($G$4:$H$23,Q21) -> 0 | W21: =COUNTIFS($I$4:$I$23,Q21) -> 1 | X21: =COUNTIFS($J$4:$K$23,Q21) -> 1 | Y21: =COUNTIFS($L$4:$L$23,Q21) -> 0 | Z21: =COUNTIFS($M$4:$N$23,Q21) -> 0 | AA21: =COUNTIFS($O$4:$O$23,Q21) -> 0 | AC21: 公共课室4 | AD21: 0 | AE21: 42 | AF21: 0 | AG21: 0 | AH21: 42 | AI21: 42
A22: 公共课室5 | B22: =COUNTIFS([1]学生编排结果!$H:$H,A22) -> 36 | C22: 王昕 | D22: 李嘉燕 | E22: 张芷欣 | F22: 侯文娟 | G22: 李智芳 | H22: 蒋思明 | I22: 王海劲 | J22: 王海劲 | K22: 李镇国 | L22: 黄楚琪 | M22: 陈坚 | N22: 郑婉慧 | O22: 钟日明 | Q22: 王海劲 | R22: =COUNTIFS($C$4:$O$23,Q22) -> 4 | S22: =+T22*150+U22*75+V22*120+W22*60+X22*165+Y22*60+Z22*120+AA22*60 -> 450 | T22: =COUNTIFS($C$4:$D$23,Q22) -> 1 | U22: =COUNTIFS($E$4:$F$23,Q22) -> 1 | V22: =COUNTIFS($G$4:$H$23,Q22) -> 0 | W22: =COUNTIFS($I$4:$I$23,Q22) -> 1 | X22: =COUNTIFS($J$4:$K$23,Q22) -> 1 | Y22: =COUNTIFS($L$4:$L$23,Q22) -> 0 | Z22: =COUNTIFS($M$4:$N$23,Q22) -> 0 | AA22: =COUNTIFS($O$4:$O$23,Q22) -> 0 | AC22: 公共课室5 | AD22: 36 (1-36) | AE22: 0 | AF22: 33 (1-33) | AG22: 8 (29-36) | AH22: 19 (1-17、34-35) | AI22: 12 (18-28、36)
A23: 公共课室6 | B23: =COUNTIFS([1]学生编排结果!$H:$H,A23) -> 25 | C23: 王海劲 | E23: 刘艳 | G23: 王帅 | I23: 李镇国 | J23: 马嘉骏 | L23: 许业琳 | M23: 周罗洁 | O23: 张玉静 | Q23: 李镇国 | R23: =COUNTIFS($C$4:$O$23,Q23) -> 4 | S23: =+T23*150+U23*75+V23*120+W23*60+X23*165+Y23*60+Z23*120+AA23*60 -> 450 | T23: =COUNTIFS($C$4:$D$23,Q23) -> 1 | U23: =COUNTIFS($E$4:$F$23,Q23) -> 1 | V23: =COUNTIFS($G$4:$H$23,Q23) -> 0 | W23: =COUNTIFS($I$4:$I$23,Q23) -> 1 | X23: =COUNTIFS($J$4:$K$23,Q23) -> 1 | Y23: =COUNTIFS($L$4:$L$23,Q23) -> 0 | Z23: =COUNTIFS($M$4:$N$23,Q23) -> 0 | AA23: =COUNTIFS($O$4:$O$23,Q23) -> 0 | AC23: 公共课室6 | AD23: 0 | AE23: 25 (1-25) | AF23: 1 (25) | AG23: 9 (16-24) | AH23: 18 (1-15、22-24) | AI23: 22 (1-21、25)
A24: 考务室：三楼报告厅1 提前30分钟到考务室签到 | Q24: 马嘉骏 | R24: =COUNTIFS($C$4:$O$23,Q24) -> 4 | S24: =+T24*150+U24*75+V24*120+W24*60+X24*165+Y24*60+Z24*120+AA24*60 -> 450 | T24: =COUNTIFS($C$4:$D$23,Q24) -> 1 | U24: =COUNTIFS($E$4:$F$23,Q24) -> 1 | V24: =COUNTIFS($G$4:$H$23,Q24) -> 0 | W24: =COUNTIFS($I$4:$I$23,Q24) -> 0 | X24: =COUNTIFS($J$4:$K$23,Q24) -> 1 | Y24: =COUNTIFS($L$4:$L$23,Q24) -> 0 | Z24: =COUNTIFS($M$4:$N$23,Q24) -> 0 | AA24: =COUNTIFS($O$4:$O$23,Q24) -> 1 | AC24: 总计 | AD24: 624 | AE24: 193 | AF24: 622 | AG24: 479 | AH24: 289 | AI24: 244
Q25: 陈映儿 | R25: =COUNTIFS($C$4:$O$23,Q25) -> 4 | S25: =+T25*150+U25*75+V25*120+W25*60+X25*165+Y25*60+Z25*120+AA25*60 -> 465 | T25: =COUNTIFS($C$4:$D$23,Q25) -> 0 | U25: =COUNTIFS($E$4:$F$23,Q25) -> 0 | V25: =COUNTIFS($G$4:$H$23,Q25) -> 1 | W25: =COUNTIFS($I$4:$I$23,Q25) -> 0 | X25: =COUNTIFS($J$4:$K$23,Q25) -> 1 | Y25: =COUNTIFS($L$4:$L$23,Q25) -> 0 | Z25: =COUNTIFS($M$4:$N$23,Q25) -> 1 | AA25: =COUNTIFS($O$4:$O$23,Q25) -> 1
Q26: 王菲飞 | R26: =COUNTIFS($C$4:$O$23,Q26) -> 4 | S26: =+T26*150+U26*75+V26*120+W26*60+X26*165+Y26*60+Z26*120+AA26*60 -> 465 | T26: =COUNTIFS($C$4:$D$23,Q26) -> 0 | U26: =COUNTIFS($E$4:$F$23,Q26) -> 0 | V26: =COUNTIFS($G$4:$H$23,Q26) -> 1 | W26: =COUNTIFS($I$4:$I$23,Q26) -> 0 | X26: =COUNTIFS($J$4:$K$23,Q26) -> 1 | Y26: =COUNTIFS($L$4:$L$23,Q26) -> 0 | Z26: =COUNTIFS($M$4:$N$23,Q26) -> 1 | AA26: =COUNTIFS($O$4:$O$23,Q26) -> 1
Q27: 梁洁楹 | R27: =COUNTIFS($C$4:$O$23,Q27) -> 4 | S27: =+T27*150+U27*75+V27*120+W27*60+X27*165+Y27*60+Z27*120+AA27*60 -> 465 | T27: =COUNTIFS($C$4:$D$23,Q27) -> 0 | U27: =COUNTIFS($E$4:$F$23,Q27) -> 0 | V27: =COUNTIFS($G$4:$H$23,Q27) -> 1 | W27: =COUNTIFS($I$4:$I$23,Q27) -> 0 | X27: =COUNTIFS($J$4:$K$23,Q27) -> 1 | Y27: =COUNTIFS($L$4:$L$23,Q27) -> 0 | Z27: =COUNTIFS($M$4:$N$23,Q27) -> 1 | AA27: =COUNTIFS($O$4:$O$23,Q27) -> 1
Q28: 陈美苑 | R28: =COUNTIFS($C$4:$O$23,Q28) -> 4 | S28: =+T28*150+U28*75+V28*120+W28*60+X28*165+Y28*60+Z28*120+AA28*60 -> 465 | T28: =COUNTIFS($C$4:$D$23,Q28) -> 0 | U28: =COUNTIFS($E$4:$F$23,Q28) -> 0 | V28: =COUNTIFS($G$4:$H$23,Q28) -> 1 | W28: =COUNTIFS($I$4:$I$23,Q28) -> 0 | X28: =COUNTIFS($J$4:$K$23,Q28) -> 1 | Y28: =COUNTIFS($L$4:$L$23,Q28) -> 0 | Z28: =COUNTIFS($M$4:$N$23,Q28) -> 1 | AA28: =COUNTIFS($O$4:$O$23,Q28) -> 1 | AD28: 4选2考试顺序
Q29: 蒋虹 | R29: =COUNTIFS($C$4:$O$23,Q29) -> 4 | S29: =+T29*150+U29*75+V29*120+W29*60+X29*165+Y29*60+Z29*120+AA29*60 -> 465 | T29: =COUNTIFS($C$4:$D$23,Q29) -> 0 | U29: =COUNTIFS($E$4:$F$23,Q29) -> 0 | V29: =COUNTIFS($G$4:$H$23,Q29) -> 1 | W29: =COUNTIFS($I$4:$I$23,Q29) -> 0 | X29: =COUNTIFS($J$4:$K$23,Q29) -> 1 | Y29: =COUNTIFS($L$4:$L$23,Q29) -> 0 | Z29: =COUNTIFS($M$4:$N$23,Q29) -> 1 | AA29: =COUNTIFS($O$4:$O$23,Q29) -> 1
Q30: 余晓娜 | R30: =COUNTIFS($C$4:$O$23,Q30) -> 4 | S30: =+T30*150+U30*75+V30*120+W30*60+X30*165+Y30*60+Z30*120+AA30*60 -> 450 | T30: =COUNTIFS($C$4:$D$23,Q30) -> 1 | U30: =COUNTIFS($E$4:$F$23,Q30) -> 1 | V30: =COUNTIFS($G$4:$H$23,Q30) -> 0 | W30: =COUNTIFS($I$4:$I$23,Q30) -> 0 | X30: =COUNTIFS($J$4:$K$23,Q30) -> 1 | Y30: =COUNTIFS($L$4:$L$23,Q30) -> 0 | Z30: =COUNTIFS($M$4:$N$23,Q30) -> 0 | AA30: =COUNTIFS($O$4:$O$23,Q30) -> 1 | AF30: 第一段 | AH30: 第二段
Q31: 王倩 | R31: =COUNTIFS($C$4:$O$23,Q31) -> 4 | S31: =+T31*150+U31*75+V31*120+W31*60+X31*165+Y31*60+Z31*120+AA31*60 -> 450 | T31: =COUNTIFS($C$4:$D$23,Q31) -> 1 | U31: =COUNTIFS($E$4:$F$23,Q31) -> 1 | V31: =COUNTIFS($G$4:$H$23,Q31) -> 0 | W31: =COUNTIFS($I$4:$I$23,Q31) -> 0 | X31: =COUNTIFS($J$4:$K$23,Q31) -> 1 | Y31: =COUNTIFS($L$4:$L$23,Q31) -> 0 | Z31: =COUNTIFS($M$4:$N$23,Q31) -> 0 | AA31: =COUNTIFS($O$4:$O$23,Q31) -> 1 | AD31: 1-11班 | AF31: 化学 | AH31: 生物
Q32: 谢晨阳 | R32: =COUNTIFS($C$4:$O$23,Q32) -> 4 | S32: =+T32*150+U32*75+V32*120+W32*60+X32*165+Y32*60+Z32*120+AA32*60 -> 450 | T32: =COUNTIFS($C$4:$D$23,Q32) -> 1 | U32: =COUNTIFS($E$4:$F$23,Q32) -> 1 | V32: =COUNTIFS($G$4:$H$23,Q32) -> 0 | W32: =COUNTIFS($I$4:$I$23,Q32) -> 0 | X32: =COUNTIFS($J$4:$K$23,Q32) -> 1 | Y32: =COUNTIFS($L$4:$L$23,Q32) -> 0 | Z32: =COUNTIFS($M$4:$N$23,Q32) -> 0 | AA32: =COUNTIFS($O$4:$O$23,Q32) -> 1 | AD32: 12-13班 | AF32: 化学 | AH32: 地理
Q33: 范南莺 | R33: =COUNTIFS($C$4:$O$23,Q33) -> 4 | S33: =+T33*150+U33*75+V33*120+W33*60+X33*165+Y33*60+Z33*120+AA33*60 -> 450 | T33: =COUNTIFS($C$4:$D$23,Q33) -> 1 | U33: =COUNTIFS($E$4:$F$23,Q33) -> 1 | V33: =COUNTIFS($G$4:$H$23,Q33) -> 0 | W33: =COUNTIFS($I$4:$I$23,Q33) -> 0 | X33: =COUNTIFS($J$4:$K$23,Q33) -> 1 | Y33: =COUNTIFS($L$4:$L$23,Q33) -> 0 | Z33: =COUNTIFS($M$4:$N$23,Q33) -> 0 | AA33: =COUNTIFS($O$4:$O$23,Q33) -> 1 | AD33: 14班 | AF33: 化学 | AH33: 政治
Q34: 罗雯雯 | R34: 请假 | S34: =+T34*150+U34*75+V34*120+W34*60+X34*165+Y34*60+Z34*120+AA34*60 -> 0 | T34: =COUNTIFS($C$4:$D$23,Q34) -> 0 | U34: =COUNTIFS($E$4:$F$23,Q34) -> 0 | V34: =COUNTIFS($G$4:$H$23,Q34) -> 0 | W34: =COUNTIFS($I$4:$I$23,Q34) -> 0 | X34: =COUNTIFS($J$4:$K$23,Q34) -> 0 | Y34: =COUNTIFS($L$4:$L$23,Q34) -> 0 | Z34: =COUNTIFS($M$4:$N$23,Q34) -> 0 | AA34: =COUNTIFS($O$4:$O$23,Q34) -> 0 | AD34: 15-公共4 | AF34: 地理 | AH34: 政治
Q35: 张妮 | R35: =COUNTIFS($C$4:$O$23,Q35) -> 5 | S35: =+T35*150+U35*75+V35*120+W35*60+X35*165+Y35*60+Z35*120+AA35*60 -> 510 | T35: =COUNTIFS($C$4:$D$23,Q35) -> 1 | U35: =COUNTIFS($E$4:$F$23,Q35) -> 1 | V35: =COUNTIFS($G$4:$H$23,Q35) -> 0 | W35: =COUNTIFS($I$4:$I$23,Q35) -> 0 | X35: =COUNTIFS($J$4:$K$23,Q35) -> 1 | Y35: =COUNTIFS($L$4:$L$23,Q35) -> 1 | Z35: =COUNTIFS($M$4:$N$23,Q35) -> 0 | AA35: =COUNTIFS($O$4:$O$23,Q35) -> 1 | AD35: 公5 | AF35: 化学（1-33） 生物（34-36） | AH35: 地理（1-17、34-35） 政治（18-28、36） 生物（29-33）
Q36: 张莉萍 | R36: =COUNTIFS($C$4:$O$23,Q36) -> 4 | S36: =+T36*150+U36*75+V36*120+W36*60+X36*165+Y36*60+Z36*120+AA36*60 -> 450 | T36: =COUNTIFS($C$4:$D$23,Q36) -> 1 | U36: =COUNTIFS($E$4:$F$23,Q36) -> 1 | V36: =COUNTIFS($G$4:$H$23,Q36) -> 0 | W36: =COUNTIFS($I$4:$I$23,Q36) -> 0 | X36: =COUNTIFS($J$4:$K$23,Q36) -> 1 | Y36: =COUNTIFS($L$4:$L$23,Q36) -> 1 | Z36: =COUNTIFS($M$4:$N$23,Q36) -> 0 | AA36: =COUNTIFS($O$4:$O$23,Q36) -> 0
Q37: 陈晓迪 | R37: =COUNTIFS($C$4:$O$23,Q37) -> 4 | S37: =+T37*150+U37*75+V37*120+W37*60+X37*165+Y37*60+Z37*120+AA37*60 -> 465 | T37: =COUNTIFS($C$4:$D$23,Q37) -> 0 | U37: =COUNTIFS($E$4:$F$23,Q37) -> 0 | V37: =COUNTIFS($G$4:$H$23,Q37) -> 1 | W37: =COUNTIFS($I$4:$I$23,Q37) -> 0 | X37: =COUNTIFS($J$4:$K$23,Q37) -> 1 | Y37: =COUNTIFS($L$4:$L$23,Q37) -> 0 | Z37: =COUNTIFS($M$4:$N$23,Q37) -> 1 | AA37: =COUNTIFS($O$4:$O$23,Q37) -> 1
Q38: 黄朝阳 | R38: =COUNTIFS($C$4:$O$23,Q38) -> 4 | S38: =+T38*150+U38*75+V38*120+W38*60+X38*165+Y38*60+Z38*120+AA38*60 -> 465 | T38: =COUNTIFS($C$4:$D$23,Q38) -> 0 | U38: =COUNTIFS($E$4:$F$23,Q38) -> 0 | V38: =COUNTIFS($G$4:$H$23,Q38) -> 1 | W38: =COUNTIFS($I$4:$I$23,Q38) -> 0 | X38: =COUNTIFS($J$4:$K$23,Q38) -> 1 | Y38: =COUNTIFS($L$4:$L$23,Q38) -> 0 | Z38: =COUNTIFS($M$4:$N$23,Q38) -> 1 | AA38: =COUNTIFS($O$4:$O$23,Q38) -> 1 | AD38: 公6 | AF38: 地理（1-15） 生物（16-24） 化学（25） | AH38: 政治（1-21） 地理（22-24） 政治（25）
Q39: 杨眉 | R39: =COUNTIFS($C$4:$O$23,Q39) -> 4 | S39: =+T39*150+U39*75+V39*120+W39*60+X39*165+Y39*60+Z39*120+AA39*60 -> 450 | T39: =COUNTIFS($C$4:$D$23,Q39) -> 1 | U39: =COUNTIFS($E$4:$F$23,Q39) -> 1 | V39: =COUNTIFS($G$4:$H$23,Q39) -> 0 | W39: =COUNTIFS($I$4:$I$23,Q39) -> 0 | X39: =COUNTIFS($J$4:$K$23,Q39) -> 1 | Y39: =COUNTIFS($L$4:$L$23,Q39) -> 1 | Z39: =COUNTIFS($M$4:$N$23,Q39) -> 0 | AA39: =COUNTIFS($O$4:$O$23,Q39) -> 0
Q40: 王玉发 | R40: =COUNTIFS($C$4:$O$23,Q40) -> 4 | S40: =+T40*150+U40*75+V40*120+W40*60+X40*165+Y40*60+Z40*120+AA40*60 -> 465 | T40: =COUNTIFS($C$4:$D$23,Q40) -> 0 | U40: =COUNTIFS($E$4:$F$23,Q40) -> 0 | V40: =COUNTIFS($G$4:$H$23,Q40) -> 1 | W40: =COUNTIFS($I$4:$I$23,Q40) -> 0 | X40: =COUNTIFS($J$4:$K$23,Q40) -> 1 | Y40: =COUNTIFS($L$4:$L$23,Q40) -> 0 | Z40: =COUNTIFS($M$4:$N$23,Q40) -> 1 | AA40: =COUNTIFS($O$4:$O$23,Q40) -> 1
...

Sheet 比对
A1: =[1]巡视!$A$1&"监考安排" -> 2025-2026学年高二第一学期期中考监考安排 | T1: 11月5日（周三） | X1: 11月6日（周四）
A2: 试室 | B2: 人数 | C2: 11月5日（周三） | J2: 11月6日（周四） | T2: 语文 | U2: 物理/历史 | V2: 数学 | W2: 政治学考 | X2: 4选2 | Y2: 自习 | Z2: 英语 | AA2: 物理学考
C3: 8:00-10:30 语文 | E3: 11:00-12:15 物理/历史 | G3: 14:30-16:30 数学 | I3: 17:00-18:00 政治学考 | J3: 8:00-10:45 4选2 | L3: 11:15-12:15 自习 | M3: 14:30-16:30 英语 | O3: 17:00-18:00 物理学考 | Q3: 姓名 | R3: 段数 | S3: 时长 | T3: 8:00-10:30 | U3: 11:00-12:15 | V3: 14:30-16:30 | W3: 17:00-18:00 | X3: 8:00-10:45 | Y3: 11:15-12:15 | Z3: 14:30-16:30 | AA3: 17:00-18:00 | AD3: 物理 | AE3: 历史 | AF3: 化学 | AG3: 生物 | AH3: 地理 | AI3: 政治 | AK3: 语文20考场 | AL3: 20*45 | AM3: =20*45 -> 900 | AN3: 50 | AO3: =AM3+AN3 -> 950
A4: 高二1班 | B4: =COUNTIFS([1]学生编排结果!$H:$H,A4) -> #VALUE! | C4: =IF(监考安排!C4='监考安排（旧）'!C4,"1",监考安排!C4) -> 1 | D4: =IF(监考安排!D4='监考安排（旧）'!D4,"1",监考安排!D4) -> 1 | E4: =IF(监考安排!E4='监考安排（旧）'!E4,"1",监考安排!E4) -> 1 | F4: =IF(监考安排!F4='监考安排（旧）'!F4,"1",监考安排!F4) -> 1 | G4: =IF(监考安排!G4='监考安排（旧）'!G4,"1",监考安排!G4) -> 郑婉慧 | H4: =IF(监考安排!H4='监考安排（旧）'!H4,"1",监考安排!H4) -> 1 | I4: =IF(监考安排!I4='监考安排（旧）'!I4,"1",监考安排!I4) -> 陈美苑 | J4: =IF(监考安排!J4='监考安排（旧）'!J4,"1",监考安排!J4) -> 1 | ... O4: =IF(监考安排!O4='监考安排（旧）'!O4,"1",监考安排!O4) -> 1 | Q4: 林蕴瑜 | R4: =COUNTIFS($C$4:$O$23,Q4) -> 2 | S4: =+T4*150+U4*75+V4*120+W4*60+X4*165+Y4*60+Z4*120+AA4*60 -> 210 | T4: =COUNTIFS($C$4:$D$23,Q4) -> 1 | U4: =COUNTIFS($E$4:$F$23,Q4) -> 0 | V4: =COUNTIFS($G$4:$H$23,Q4) -> 0 | W4: =COUNTIFS($I$4:$I$23,Q4) -> 0 | X4: =COUNTIFS($J$4:$K$23,Q4) -> 0 | Y4: =COUNTIFS($L$4:$L$23,Q4) -> 0 | Z4: =COUNTIFS($M$4:$N$23,Q4) -> 0 | AA4: =COUNTIFS($O$4:$O$23,Q4) -> 1 | AC4: 高二1班 | AD4: 42 | AE4: 0 | AF4: 42 | AG4: 42 | AH4: 0 | AI4: 0 | AK4: 数学20考场 | AL4: 20*45 | AM4: =20*45 -> 900 | AN4: 50 | AO4: =AM4+AN4 -> 950
A5: 高二2班 | B5: =COUNTIFS([1]学生编排结果!$H:$H,A5) -> #VALUE! | C5: =IF(监考安排!C5='监考安排（旧）'!C5,"1",监考安排!C5) -> 王倩 | D5: =IF(监考安排!D5='监考安排（旧）'!D5,"1",监考安排!D5) -> 1 | E5: =IF(监考安排!E5='监考安排（旧）'!E5,"1",监考安排!E5) -> 1 | F5: =IF(监考安排!F5='监考安排（旧）'!F5,"1",监考安排!F5) -> 1 | G5: =IF(监考安排!G5='监考安排（旧）'!G5,"1",监考安排!G5) -> 1 | H5: =IF(监考安排!H5='监考安排（旧）'!H5,"1",监考安排!H5) -> 1 | I5: =IF(监考安排!I5='监考安排（旧）'!I5,"1",监考安排!I5) -> 王菲飞 | J5: =IF(监考安排!J5='监考安排（旧）'!J5,"1",监考安排!J5) -> 1 | ... O5: =IF(监考安排!O5='监考安排（旧）'!O5,"1",监考安排!O5) -> 1 | Q5: 明珊珊 | R5: =COUNTIFS($C$4:$O$23,Q5) -> 2 | S5: =+T5*150+U5*75+V5*120+W5*60+X5*165+Y5*60+Z5*120+AA5*60 -> 210 | T5: =COUNTIFS($C$4:$D$23,Q5) -> 1 | U5: =COUNTIFS($E$4:$F$23,Q5) -> 0 | V5: =COUNTIFS($G$4:$H$23,Q5) -> 0 | W5: =COUNTIFS($I$4:$I$23,Q5) -> 0 | X5: =COUNTIFS($J$4:$K$23,Q5) -> 0 | Y5: =COUNTIFS($L$4:$L$23,Q5) -> 0 | Z5: =COUNTIFS($M$4:$N$23,Q5) -> 0 | AA5: =COUNTIFS($O$4:$O$23,Q5) -> 1 | AC5: 高二2班 | AD5: 42 | AE5: 0 | AF5: 42 | AG5: 42 | AH5: 0 | AI5: 0 | AK5: 英语20考场 | AL5: 20*45 | AM5: =20*45 -> 900 | AN5: 50 | AO5: =AM5+AN5 -> 950
A6: 高二3班 | B6: =COUNTIFS([1]学生编排结果!$H:$H,A6) -> #VALUE! | C6: =IF(监考安排!C6='监考安排（旧）'!C6,"1",监考安排!C6) -> 1 | D6: =IF(监考安排!D6='监考安排（旧）'!D6,"1",监考安排!D6) -> 1 | E6: =IF(监考安排!E6='监考安排（旧）'!E6,"1",监考安排!E6) -> 1 | F6: =IF(监考安排!F6='监考安排（旧）'!F6,"1",监考安排!F6) -> 1 | G6: =IF(监考安排!G6='监考安排（旧）'!G6,"1",监考安排!G6) -> 1 | H6: =IF(监考安排!H6='监考安排（旧）'!H6,"1",监考安排!H6) -> 1 | I6: =IF(监考安排!I6='监考安排（旧）'!I6,"1",监考安排!I6) -> 1 | J6: =IF(监考安排!J6='监考安排（旧）'!J6,"1",监考安排!J6) -> 1 | ... O6: =IF(监考安排!O6='监考安排（旧）'!O6,"1",监考安排!O6) -> 明珊珊 | Q6: 蒋思明 | R6: =COUNTIFS($C$4:$O$23,Q6) -> 0 | S6: =+T6*150+U6*75+V6*120+W6*60+X6*165+Y6*60+Z6*120+AA6*60 -> 0 | T6: =COUNTIFS($C$4:$D$23,Q6) -> 0 | U6: =COUNTIFS($E$4:$F$23,Q6) -> 0 | V6: =COUNTIFS($G$4:$H$23,Q6) -> 0 | W6: =COUNTIFS($I$4:$I$23,Q6) -> 0 | X6: =COUNTIFS($J$4:$K$23,Q6) -> 0 | Y6: =COUNTIFS($L$4:$L$23,Q6) -> 0 | Z6: =COUNTIFS($M$4:$N$23,Q6) -> 0 | AA6: =COUNTIFS($O$4:$O$23,Q6) -> 0 | AC6: 高二3班 | AD6: 42 | AE6: 0 | AF6: 42 | AG6: 42 | AH6: 0 | AI6: 0 | AK6: 物理15考场 | AL6: 15*45 | AM6: =15*45 -> 675 | AN6: 50 | AO6: =AM6+AN6 -> 725
A7: 高二4班 | B7: =COUNTIFS([1]学生编排结果!$H:$H,A7) -> #VALUE! | C7: =IF(监考安排!C7='监考安排（旧）'!C7,"1",监考安排!C7) -> 1 | D7: =IF(监考安排!D7='监考安排（旧）'!D7,"1",监考安排!D7) -> 1 | E7: =IF(监考安排!E7='监考安排（旧）'!E7,"1",监考安排!E7) -> 1 | F7: =IF(监考安排!F7='监考安排（旧）'!F7,"1",监考安排!F7) -> 1 | G7: =IF(监考安排!G7='监考安排（旧）'!G7,"1",监考安排!G7) -> 1 | H7: =IF(监考安排!H7='监考安排（旧）'!H7,"1",监考安排!H7) -> 1 | I7: =IF(监考安排!I7='监考安排（旧）'!I7,"1",监考安排!I7) -> 1 | J7: =IF(监考安排!J7='监考安排（旧）'!J7,"1",监考安排!J7) -> 李智芳 | ... O7: =IF(监考安排!O7='监考安排（旧）'!O7,"1",监考安排!O7) -> 1 | Q7: 吕雪容 | R7: =COUNTIFS($C$4:$O$23,Q7) -> 0 | S7: =+T7*150+U7*75+V7*120+W7*60+X7*165+Y7*60+Z7*120+AA7*60 -> 0 | T7: =COUNTIFS($C$4:$D$23,Q7) -> 0 | U7: =COUNTIFS($E$4:$F$23,Q7) -> 0 | V7: =COUNTIFS($G$4:$H$23,Q7) -> 0 | W7: =COUNTIFS($I$4:$I$23,Q7) -> 0 | X7: =COUNTIFS($J$4:$K$23,Q7) -> 0 | Y7: =COUNTIFS($L$4:$L$23,Q7) -> 0 | Z7: =COUNTIFS($M$4:$N$23,Q7) -> 0 | AA7: =COUNTIFS($O$4:$O$23,Q7) -> 0 | AC7: 高二4班 | AD7: 42 | AE7: 0 | AF7: 42 | AG7: 42 | AH7: 0 | AI7: 0 | AK7: 历史5考场 | AL7: 5*45 | AM7: =5*45 -> 225 | AN7: 25 | AO7: =AM7+AN7 -> 250
A8: 高二5班 | B8: =COUNTIFS([1]学生编排结果!$H:$H,A8) -> #VALUE! | C8: =IF(监考安排!C8='监考安排（旧）'!C8,"1",监考安排!C8) -> 林蕴瑜 | D8: =IF(监考安排!D8='监考安排（旧）'!D8,"1",监考安排!D8) -> 1 | E8: =IF(监考安排!E8='监考安排（旧）'!E8,"1",监考安排!E8) -> 1 | F8: =IF(监考安排!F8='监考安排（旧）'!F8,"1",监考安排!F8) -> 1 | G8: =IF(监考安排!G8='监考安排（旧）'!G8,"1",监考安排!G8) -> 1 | H8: =IF(监考安排!H8='监考安排（旧）'!H8,"1",监考安排!H8) -> 1 | I8: =IF(监考安排!I8='监考安排（旧）'!I8,"1",监考安排!I8) -> 1 | J8: =IF(监考安排!J8='监考安排（旧）'!J8,"1",监考安排!J8) -> 1 | ... O8: =IF(监考安排!O8='监考安排（旧）'!O8,"1",监考安排!O8) -> 林蕴瑜 | Q8: 彭海影 | R8: =COUNTIFS($C$4:$O$23,Q8) -> 2 | S8: =+T8*150+U8*75+V8*120+W8*60+X8*165+Y8*60+Z8*120+AA8*60 -> 210 | T8: =COUNTIFS($C$4:$D$23,Q8) -> 1 | U8: =COUNTIFS($E$4:$F$23,Q8) -> 0 | V8: =COUNTIFS($G$4:$H$23,Q8) -> 0 | W8: =COUNTIFS($I$4:$I$23,Q8) -> 0 | X8: =COUNTIFS($J$4:$K$23,Q8) -> 0 | Y8: =COUNTIFS($L$4:$L$23,Q8) -> 0 | Z8: =COUNTIFS($M$4:$N$23,Q8) -> 0 | AA8: =COUNTIFS($O$4:$O$23,Q8) -> 1 | AC8: 高二5班 | AD8: 42 | AE8: 0 | AF8: 42 | AG8: 42 | AH8: 0 | AI8: 0 | AK8: 化学16考场 | AL8: 16*45 | AM8: =16*45 -> 720 | AN8: 0 | AO8: =AM8+AN8 -> 720
A9: 高二6班 | B9: =COUNTIFS([1]学生编排结果!$H:$H,A9) -> #VALUE! | C9: =IF(监考安排!C9='监考安排（旧）'!C9,"1",监考安排!C9) -> 1 | D9: =IF(监考安排!D9='监考安排（旧）'!D9,"1",监考安排!D9) -> 1 | E9: =IF(监考安排!E9='监考安排（旧）'!E9,"1",监考安排!E9) -> 1 | F9: =IF(监考安排!F9='监考安排（旧）'!F9,"1",监考安排!F9) -> 1 | G9: =IF(监考安排!G9='监考安排（旧）'!G9,"1",监考安排!G9) -> 1 | H9: =IF(监考安排!H9='监考安排（旧）'!H9,"1",监考安排!H9) -> 1 | I9: =IF(监考安排!I9='监考安排（旧）'!I9,"1",监考安排!I9) -> 李昕雨 | J9: =IF(监考安排!J9='监考安排（旧）'!J9,"1",监考安排!J9) -> 1 | ... O9: =IF(监考安排!O9='监考安排（旧）'!O9,"1",监考安排!O9) -> 许业琳 | Q9: 张光礼 | R9: =COUNTIFS($C$4:$O$23,Q9) -> 0 | S9: =+T9*150+U9*75+V9*120+W9*60+X9*165+Y9*60+Z9*120+AA9*60 -> 0 | T9: =COUNTIFS($C$4:$D$23,Q9) -> 0 | U9: =COUNTIFS($E$4:$F$23,Q9) -> 0 | V9: =COUNTIFS($G$4:$H$23,Q9) -> 0 | W9: =COUNTIFS($I$4:$I$23,Q9) -> 0 | X9: =COUNTIFS($J$4:$K$23,Q9) -> 0 | Y9: =COUNTIFS($L$4:$L$23,Q9) -> 0 | Z9: =COUNTIFS($M$4:$N$23,Q9) -> 0 | AA9: =COUNTIFS($O$4:$O$23,Q9) -> 0 | AC9: 高二6班 | AD9: 42 | AE9: 0 | AF9: 42 | AG9: 42 | AH9: 0 | AI9: 0 | AK9: 生物12考场 | AL9: 12*45 | AM9: =12*45 -> 540 | AN9: 0 | AO9: =AM9+AN9 -> 540
A10: 高二7班 | B10: =COUNTIFS([1]学生编排结果!$H:$H,A10) -> #VALUE! | C10: =IF(监考安排!C10='监考安排（旧）'!C10,"1",监考安排!C10) -> 周罗洁 | D10: =IF(监考安排!D10='监考安排（旧）'!D10,"1",监考安排!D10) -> 1 | E10: =IF(监考安排!E10='监考安排（旧）'!E10,"1",监考安排!E10) -> 1 | F10: =IF(监考安排!F10='监考安排（旧）'!F10,"1",监考安排!F10) -> 1 | G10: =IF(监考安排!G10='监考安排（旧）'!G10,"1",监考安排!G10) -> 1 | H10: =IF(监考安排!H10='监考安排（旧）'!H10,"1",监考安排!H10) -> 1 | I10: =IF(监考安排!I10='监考安排（旧）'!I10,"1",监考安排!I10) -> 1 | J10: =IF(监考安排!J10='监考安排（旧）'!J10,"1",监考安排!J10) -> 1 | ... O10: =IF(监考安排!O10='监考安排（旧）'!O10,"1",监考安排!O10) -> 1 | Q10: 赵香甜 | R10: =COUNTIFS($C$4:$O$23,Q10) -> 0 | S10: =+T10*150+U10*75+V10*120+W10*60+X10*165+Y10*60+Z10*120+AA10*60 -> 0 | T10: =COUNTIFS($C$4:$D$23,Q10) -> 0 | U10: =COUNTIFS($E$4:$F$23,Q10) -> 0 | V10: =COUNTIFS($G$4:$H$23,Q10) -> 0 | W10: =COUNTIFS($I$4:$I$23,Q10) -> 0 | X10: =COUNTIFS($J$4:$K$23,Q10) -> 0 | Y10: =COUNTIFS($L$4:$L$23,Q10) -> 0 | Z10: =COUNTIFS($M$4:$N$23,Q10) -> 0 | AA10: =COUNTIFS($O$4:$O$23,Q10) -> 0 | AC10: 高二7班 | AD10: 42 | AE10: 0 | AF10: 42 | AG10: 42 | AH10: 0 | AI10: 0 | AK10: 地理8考场 | AL10: 8*45 | AM10: =8*45 -> 360 | AN10: 0 | AO10: =AM10+AN10 -> 360
A11: 高二8班 | B11: =COUNTIFS([1]学生编排结果!$H:$H,A11) -> #VALUE! | C11: =IF(监考安排!C11='监考安排（旧）'!C11,"1",监考安排!C11) -> 1 | D11: =IF(监考安排!D11='监考安排（旧）'!D11,"1",监考安排!D11) -> 1 | E11: =IF(监考安排!E11='监考安排（旧）'!E11,"1",监考安排!E11) -> 1 | F11: =IF(监考安排!F11='监考安排（旧）'!F11,"1",监考安排!F11) -> 1 | G11: =IF(监考安排!G11='监考安排（旧）'!G11,"1",监考安排!G11) -> 1 | H11: =IF(监考安排!H11='监考安排（旧）'!H11,"1",监考安排!H11) -> 1 | I11: =IF(监考安排!I11='监考安排（旧）'!I11,"1",监考安排!I11) -> 1 | J11: =IF(监考安排!J11='监考安排（旧）'!J11,"1",监考安排!J11) -> 1 | ... O11: =IF(监考安排!O11='监考安排（旧）'!O11,"1",监考安排!O11) -> 1 | Q11: 段蕴瑶 | R11: =COUNTIFS($C$4:$O$23,Q11) -> 0 | S11: =+T11*150+U11*75+V11*120+W11*60+X11*165+Y11*60+Z11*120+AA11*60 -> 0 | T11: =COUNTIFS($C$4:$D$23,Q11) -> 0 | U11: =COUNTIFS($E$4:$F$23,Q11) -> 0 | V11: =COUNTIFS($G$4:$H$23,Q11) -> 0 | W11: =COUNTIFS($I$4:$I$23,Q11) -> 0 | X11: =COUNTIFS($J$4:$K$23,Q11) -> 0 | Y11: =COUNTIFS($L$4:$L$23,Q11) -> 0 | Z11: =COUNTIFS($M$4:$N$23,Q11) -> 0 | AA11: =COUNTIFS($O$4:$O$23,Q11) -> 0 | AC11: 高二8班 | AD11: 42 | AE11: 0 | AF11: 42 | AG11: 42 | AH11: 0 | AI11: 0 | AK11: 政治7考场 | AL11: 7*45 | AM11: =7*45 -> 315 | AO11: =AM11+AN11 -> 315
A12: 高二9班 | B12: =COUNTIFS([1]学生编排结果!$H:$H,A12) -> #VALUE! | C12: =IF(监考安排!C12='监考安排（旧）'!C12,"1",监考安排!C12) -> 1 | D12: =IF(监考安排!D12='监考安排（旧）'!D12,"1",监考安排!D12) -> 1 | E12: =IF(监考安排!E12='监考安排（旧）'!E12,"1",监考安排!E12) -> 1 | F12: =IF(监考安排!F12='监考安排（旧）'!F12,"1",监考安排!F12) -> 1 | G12: =IF(监考安排!G12='监考安排（旧）'!G12,"1",监考安排!G12) -> 1 | H12: =IF(监考安排!H12='监考安排（旧）'!H12,"1",监考安排!H12) -> 刘良桂 | I12: =IF(监考安排!I12='监考安排（旧）'!I12,"1",监考安排!I12) -> 1 | J12: =IF(监考安排!J12='监考安排（旧）'!J12,"1",监考安排!J12) -> 1 | ... O12: =IF(监考安排!O12='监考安排（旧）'!O12,"1",监考安排!O12) -> 1 | Q12: 钟三明 | R12: =COUNTIFS($C$4:$O$23,Q12) -> 0 | S12: =+T12*150+U12*75+V12*120+W12*60+X12*165+Y12*60+Z12*120+AA12*60 -> 0 | T12: =COUNTIFS($C$4:$D$23,Q12) -> 0 | U12: =COUNTIFS($E$4:$F$23,Q12) -> 0 | V12: =COUNTIFS($G$4:$H$23,Q12) -> 0 | W12: =COUNTIFS($I$4:$I$23,Q12) -> 0 | X12: =COUNTIFS($J$4:$K$23,Q12) -> 0 | Y12: =COUNTIFS($L$4:$L$23,Q12) -> 0 | Z12: =COUNTIFS($M$4:$N$23,Q12) -> 0 | AA12: =COUNTIFS($O$4:$O$23,Q12) -> 0 | AC12: 高二9班 | AD12: 42 | AE12: 0 | AF12: 42 | AG12: 42 | AH12: 0 | AI12: 0
A13: 高二10班 | B13: =COUNTIFS([1]学生编排结果!$H:$H,A13) -> #VALUE! | C13: =IF(监考安排!C13='监考安排（旧）'!C13,"1",监考安排!C13) -> 1 | D13: =IF(监考安排!D13='监考安排（旧）'!D13,"1",监考安排!D13) -> 1 | E13: =IF(监考安排!E13='监考安排（旧）'!E13,"1",监考安排!E13) -> 1 | F13: =IF(监考安排!F13='监考安排（旧）'!F13,"1",监考安排!F13) -> 1 | G13: =IF(监考安排!G13='监考安排（旧）'!G13,"1",监考安排!G13) -> 张妮 | H13: =IF(监考安排!H13='监考安排（旧）'!H13,"1",监考安排!H13) -> 1 | I13: =IF(监考安排!I13='监考安排（旧）'!I13,"1",监考安排!I13) -> 1 | J13: =IF(监考安排!J13='监考安排（旧）'!J13,"1",监考安排!J13) -> 1 | ... O13: =IF(监考安排!O13='监考安排（旧）'!O13,"1",监考安排!O13) -> 1 | Q13: 曹芳 | R13: =COUNTIFS($C$4:$O$23,Q13) -> 0 | S13: =+T13*150+U13*75+V13*120+W13*60+X13*165+Y13*60+Z13*120+AA13*60 -> 0 | T13: =COUNTIFS($C$4:$D$23,Q13) -> 0 | U13: =COUNTIFS($E$4:$F$23,Q13) -> 0 | V13: =COUNTIFS($G$4:$H$23,Q13) -> 0 | W13: =COUNTIFS($I$4:$I$23,Q13) -> 0 | X13: =COUNTIFS($J$4:$K$23,Q13) -> 0 | Y13: =COUNTIFS($L$4:$L$23,Q13) -> 0 | Z13: =COUNTIFS($M$4:$N$23,Q13) -> 0 | AA13: =COUNTIFS($O$4:$O$23,Q13) -> 0 | AC13: 高二10班 | AD13: 42 | AE13: 0 | AF13: 42 | AG13: 42 | AH13: 0 | AI13: 0 | AK13: 物理学考20考场 | AL13: 20*45 | AM13: =20*45 -> 900 | AN13: 50 | AO13: =AM13+AN13 -> 950
